Workbook
Name _1Excel_BuiltIn_Database_1_1: #REF!
Name _2Excel_BuiltIn_Print_Area_5_1: #REF!
Name _Hlk156713282_5: #REF!
Name Drage: #REF!
Name Drage_14: #REF!
Name Drage_2: #REF!
Name Drage_3: #REF!
Name Drage_6: #REF!
Name Drage_6_14: #REF!
Name Excel_BuiltIn__FilterDatabase_1: #REF!
Name Excel_BuiltIn__FilterDatabase_1_1: #REF!
Name Excel_BuiltIn__FilterDatabase_5: #REF!
Name Excel_BuiltIn__FilterDatabase_5_1: #REF!
Name Excel_BuiltIn__FilterDatabase_5_6: #REF!
Name Excel_BuiltIn_Database: #REF!
Name Excel_BuiltIn_Database_1: #REF!
Name Excel_BuiltIn_Database_2: #REF!
Name Excel_BuiltIn_Database_3: #REF!
Name Excel_BuiltIn_Print_Area_18: #REF!
Name Excel_BuiltIn_Print_Area_5: #REF!
Name Excel_BuiltIn_Print_Area_6: #REF!
Name g: '[1]Karamel Vyr Price'!$R$81:$R$84
Name g_3: '[1]Karamel Vyr Price'!$R$81:$R$84
Name g_5: '[1]Karamel Vyr Price'!$R$81:$R$84
Name Iris: #REF!
Name Iris_14: #REF!
Name Iris_2: #REF!
Name Iris_3: #REF!
Name Iris_6: #REF!
Name Iris_6_14: #REF!
Name Karamel: #REF!
Name Karamel_14: #REF!
Name Karamel_2: #REF!
Name Karamel_3: #REF!
Name Karamel_6: #REF!
Name Karamel_6_14: #REF!
Name KEKSY: '[2]Bisquet Plan Price'!$R$108:$R$110
Name KEKSY_3: #REF!
Name KEKSY_5: '[2]Bisquet Plan Price'!$R$108:$R$110
Name KEKSY_6: '[2]Bisquet Plan Price'!$R$108:$R$110
Name Konditer: '[2]Sweet Plan Price'!$R$66:$R$103
Name Konditer_3: #REF!
Name Konditer_5: '[2]Sweet Plan Price'!$R$66:$R$103
Name Konditer_6: '[2]Sweet Plan Price'!$R$66:$R$103
Name Marmelad: '[2]Sweet Plan Price'!$R$122:$R$127
Name Marmelad_3: #REF!
Name Marmelad_5: '[2]Sweet Plan Price'!$R$122:$R$127
Name Marmelad_6: '[2]Sweet Plan Price'!$R$122:$R$127
Name NEGLAZUR: '[2]Sweet Plan Price'!$R$110:$R$113
Name NEGLAZUR_3: #REF!
Name NEGLAZUR_5: '[2]Sweet Plan Price'!$R$110:$R$113
Name NEGLAZUR_6: '[2]Sweet Plan Price'!$R$110:$R$113
Name Print_Area: 'Солар Вест'!$A$1:$BS$80
Name Pryami: #REF!
Name Pryami_14: #REF!
Name Pryami_2: #REF!
Name Pryami_3: #REF!
Name Pryami_5: #REF!
Name SHIDNI: '[2]Sweet Plan Price'!$R$119:$R$119
Name SHIDNI_3: #REF!

Sheet Заг.
B1: "ЗАТВЕРДЖУЮ"
B2: Генеральний директор
B3: ТзОВ "Волвест Груп"
B4: Корсак В.І. ______________
A5: Звіт про рух грошових коштів (КЕШ-ФЛО), грн
B6: Солар Вест Буд
B7: 2025 | C7: Січень | F7: Січень | I7: Лютий | L7: Лютий | O7: Березень | R7: Березень | U7: Квітень | X7: Квітень | AA7: Травень | AD7: Травень | AG7: Червень | AJ7: Червень | AM7: Липень | AP7: Липень | AS7: Серпень | AV7: Серпень | AY7: Вересень | BB7: Вересень | BE7: Жовтень | BH7: Жовтень | BK7: Листопад | BN7: Листопад | BQ7: Грудень | BT7: Грудень | BW7: Разом 2025 | BZ7: Разом 2025
B8: Залишок на початок | E8: =+D8+C8 -> 0 | F8: 26870.52 | G8: 42072 | H8: =+G8+F8 -> 68942.52 | K8: =+J8+I8 -> 0 | L8: =+F72 -> 6935.15 | M8: =+G72 -> 70184 | N8: =+M8+L8 -> 77119.15 | Q8: =+P8+O8 -> 0 | R8: =+L72 -> 17482.21 | S8: =+M72 -> 68137 | T8: =+S8+R8 -> 85619.21 | W8: =+V8+U8 -> 0 | X8: =+R72 -> 314119.37 | Y8: =+S72 -> 152076 | Z8: =+Y8+X8 -> 466195.37 | AC8: =+AB8+AA8 -> 0 | AD8: =+X72 -> 151289.85 | AE8: =+Y72 -> 341770 | AF8: =+AE8+AD8 -> 493059.85 | AI8: =+AH8+AG8 -> 0 | AJ8: =+AD72 -> 118305.4 | AK8: =+AE72 -> 499081 | AL8: =+AK8+AJ8 -> 617386.4 | AO8: =+AN8+AM8 -> 0 | AP8: =+AJ72 -> 203802.98 | AQ8: =+AK72 -> 445831 | AR8: =+AQ8+AP8 -> 649633.98 | AU8: =+AT8+AS8 -> 0 | AV8: =+AP72 -> 586048.84 | AW8: =+AQ72 -> 175836 | AX8: =+AW8+AV8 -> 761884.84 | BA8: =+AZ8+AY8 -> 0 | BB8: =+AV72 -> 68141.51 | BC8: =+AW72 -> 47388 | BD8: =+BC8+BB8 -> 115529.51 | BG8: =+BF8+BE8 -> 0 | BH8: =+BB72 -> 548793.92 | BI8: =+BC72 -> 61285 | BJ8: =+BI8+BH8 -> 610078.92 | BM8: =+BL8+BK8 -> 0 | BN8: =+BH72 -> 548793.92 | BO8: =+BI72 -> 61285 | BP8: =+BO8+BN8 -> 610078.92 | BS8: =+BR8+BQ8 -> 0 | BT8: =+BN72 -> 548793.92 | BU8: =+BO72 -> 61285 | BV8: =+BU8+BT8 -> 610078.92 | BY8: =+BX8+BW8 -> 0 | BZ8: =+BT72 -> 548793.92 | CA8: =+BU72 -> 61285 | CB8: =+CA8+BZ8 -> 610078.92
B9: 2025 | C9: План | F9: Факт | I9: План | L9: Факт | O9: План | R9: Факт | U9: План | X9: Факт | AA9: План | AD9: Факт | AG9: План | AJ9: Факт | AM9: План | AP9: Факт | AS9: План | AV9: Факт | AY9: План | BB9: Факт | BE9: План | BH9: Факт | BK9: План | BN9: Факт | BQ9: План | BT9: Факт | BW9: План | BZ9: Факт
A10: Код | B10: Стаття | C10: Банк + каса | D10: @ | E10: Разом | F10: Банк + каса | G10: @ | H10: Разом | I10: Банк + каса | J10: @ | K10: Разом | L10: Банк + каса | M10: @ | N10: Разом | O10: Банк + каса | P10: @ | Q10: Разом | R10: Банк + каса | S10: @ | T10: Разом | U10: Банк + каса | V10: @ | W10: Разом | X10: Банк + каса | Y10: @ | Z10: Разом | AA10: Банк + каса | AB10: @ | AC10: Разом | AD10: Банк + каса | AE10: @ | AF10: Разом | AG10: Банк + каса | AH10: @ | AI10: Разом | AJ10: Банк + каса | AK10: @ | AL10: Разом | AM10: Банк + каса | AN10: @ | AO10: Разом | AP10: Банк + каса | AQ10: @ | AR10: Разом | AS10: Банк + каса | AT10: @ | AU10: Разом | AV10: Банк + каса | AW10: @ | AX10: Разом | AY10: Банк + каса | AZ10: @ | BA10: Разом | BB10: Банк + каса | BC10: @ | BD10: Разом | BE10: Банк + каса | BF10: @ | BG10: Разом | BH10: Банк + каса | BI10: @ | BJ10: Разом | BK10: Банк + каса | BL10: @ | BM10: Разом | BN10: Банк + каса | BO10: @ | BP10: Разом | BQ10: Банк + каса | BR10: @ | BS10: Разом | BT10: Банк + каса | BU10: @ | BV10: Разом | BW10: Банк + каса | BX10: @ | BY10: Разом | BZ10: Банк + каса | CA10: @ | CB10: Разом
A11: Надходження
A12: 111 | B12: Дохід від реалізації продукції | C12: ='[5]ПП ВДГ'!C12+'[5]Корсак Л.Р.'!C12+'[5]Корсак В.І.'!C12+[5]Конякіна!C12 -> 0 | D12: ='[5]ПП ВДГ'!D12+'[5]Корсак Л.Р.'!D12+'[5]Корсак В.І.'!D12+[5]Конякіна!D12 -> 0 | E12: =SUM(C12:D12) -> 0 | F12: ='Солар Вест'!F12+Будник!F12 -> 0 | G12: ='Солар Вест'!G12+Будник!G12 -> 0 | H12: =SUM(F12:G12) -> 0 | I12: ='[5]ПП ВДГ'!I12+'[5]Корсак Л.Р.'!I12+'[5]Корсак В.І.'!I12+[5]Конякіна!I12 -> 0 | J12: ='[5]ПП ВДГ'!J12+'[5]Корсак Л.Р.'!J12+'[5]Корсак В.І.'!J12+[5]Конякіна!J12 -> 0 | K12: =SUM(I12:J12) -> 0 | L12: ='Солар Вест'!L12+Будник!L12 -> 0 | M12: ='Солар Вест'!M12+Будник!M12 -> 0 | N12: =SUM(L12:M12) -> 0 | O12: ='[5]ПП ВДГ'!O12+'[5]Корсак Л.Р.'!O12+'[5]Корсак В.І.'!O12+[5]Конякіна!O12 -> 0 | P12: ='[5]ПП ВДГ'!P12+'[5]Корсак Л.Р.'!P12+'[5]Корсак В.І.'!P12+[5]Конякіна!P12 -> 0 | Q12: =SUM(O12:P12) -> 0 | R12: ='Солар Вест'!R12+Будник!R12 -> 0 | S12: ='Солар Вест'!S12+Будник!S12 -> 0 | T12: =SUM(R12:S12) -> 0 | U12: ='[5]ПП ВДГ'!U12+'[5]Корсак Л.Р.'!U12+'[5]Корсак В.І.'!U12+[5]Конякіна!U12 -> 0 | V12: ='[5]ПП ВДГ'!V12+'[5]Корсак Л.Р.'!V12+'[5]Корсак В.І.'!V12+[5]Конякіна!V12 -> 0 | W12: =SUM(U12:V12) -> 0 | X12: ='Солар Вест'!X12+Будник!X12 -> 0 | Y12: ='Солар Вест'!Y12+Будник!Y12 -> 0 | Z12: =SUM(X12:Y12) -> 0 | AA12: ='[5]ПП ВДГ'!AA12+'[5]Корсак Л.Р.'!AA12+'[5]Корсак В.І.'!AA12+[5]Конякіна!AA12 -> 0 | AB12: ='[5]ПП ВДГ'!AB12+'[5]Корсак Л.Р.'!AB12+'[5]Корсак В.І.'!AB12+[5]Конякіна!AB12 -> 0 | AC12: =SUM(AA12:AB12) -> 0 | AD12: ='Солар Вест'!AD12+Будник!AD12 -> 0 | AE12: ='Солар Вест'!AE12+Будник!AE12 -> 0 | AF12: =SUM(AD12:AE12) -> 0 | AG12: ='[5]ПП ВДГ'!AG12+'[5]Корсак Л.Р.'!AG12+'[5]Корсак В.І.'!AG12+[5]Конякіна!AG12 -> 0 | AH12: ='[5]ПП ВДГ'!AH12+'[5]Корсак Л.Р.'!AH12+'[5]Корсак В.І.'!AH12+[5]Конякіна!AH12 -> 0 | AI12: =SUM(AG12:AH12) -> 0 | AJ12: ='Солар Вест'!AJ12+Будник!AJ12 -> 0 | AK12: ='Солар Вест'!AK12+Будник!AK12 -> 0 | AL12: =SUM(AJ12:AK12) -> 0 | AM12: ='[5]ПП ВДГ'!AM12+'[5]Корсак Л.Р.'!AM12+'[5]Корсак В.І.'!AM12+[5]Конякіна!AM12 -> 0 | AN12: ='[5]ПП ВДГ'!AN12+'[5]Корсак Л.Р.'!AN12+'[5]Корсак В.І.'!AN12+[5]Конякіна!AN12 -> 0 | AO12: =SUM(AM12:AN12) -> 0 | AP12: ='Солар Вест'!AP12+Будник!AP12 -> 0 | AQ12: ='Солар Вест'!AQ12+Будник!AQ12 -> 0 | AR12: =SUM(AP12:AQ12) -> 0 | AS12: ='[5]ПП ВДГ'!AS12+'[5]Корсак Л.Р.'!AS12+'[5]Корсак В.І.'!AS12+[5]Конякіна!AS12 -> 0 | AT12: ='[5]ПП ВДГ'!AT12+'[5]Корсак Л.Р.'!AT12+'[5]Корсак В.І.'!AT12+[5]Конякіна!AT12 -> 0 | AU12: =SUM(AS12:AT12) -> 0 | AV12: ='Солар Вест'!AV12+Будник!AV12 -> 0 | AW12: ='Солар Вест'!AW12+Будник!AW12 -> 0 | AX12: =SUM(AV12:AW12) -> 0 | AY12: ='[5]ПП ВДГ'!AY12+'[5]Корсак Л.Р.'!AY12+'[5]Корсак В.І.'!AY12+[5]Конякіна!AY12 -> 0 | AZ12: ='[5]ПП ВДГ'!AZ12+'[5]Корсак Л.Р.'!AZ12+'[5]Корсак В.І.'!AZ12+[5]Конякіна!AZ12 -> 0 | BA12: =SUM(AY12:AZ12) -> 0 | BB12: ='Солар Вест'!BB12+Будник!BB12 -> 0 | BC12: ='Солар Вест'!BC12+Будник!BC12 -> 0 | BD12: =SUM(BB12:BC12) -> 0 | BE12: ='Солар Вест'!BE12+Будник!BE12 -> 0 | BF12: ='Солар Вест'!BF12+Будник!BF12 -> 0 | BG12: =SUM(BE12:BF12) -> 0 | BH12: ='Солар Вест'!BH12+Будник!BH12 -> 0 | BI12: ='Солар Вест'!BI12+Будник!BI12 -> 0 | BJ12: =SUM(BH12:BI12) -> 0 | BK12: ='[5]ПП ВДГ'!BK12+'[5]Корсак Л.Р.'!BK12+'[5]Корсак В.І.'!BK12+[5]Конякіна!BK12 -> 0 | BL12: ='[5]ПП ВДГ'!BL12+'[5]Корсак Л.Р.'!BL12+'[5]Корсак В.І.'!BL12+[5]Конякіна!BL12 -> 0 | BM12: =SUM(BK12:BL12) -> 0 | BN12: ='Солар Вест'!BN12+Будник!BN12 -> 0 | BO12: ='Солар Вест'!BO12+Будник!BO12 -> 0 | BP12: =SUM(BN12:BO12) -> 0 | BQ12: ='[5]ПП ВДГ'!BQ12+'[5]Корсак Л.Р.'!BQ12+'[5]Корсак В.І.'!BQ12+[5]Конякіна!BQ12 -> 0 | BR12: ='[5]ПП ВДГ'!BR12+'[5]Корсак Л.Р.'!BR12+'[5]Корсак В.І.'!BR12+[5]Конякіна!BR12 -> 0 | BS12: =SUM(BQ12:BR12) -> 0 | BT12: ='Солар Вест'!BT12+Будник!BT12 -> 0 | BU12: ='Солар Вест'!BU12+Будник!BU12 -> 0 | BV12: =SUM(BT12:BU12) -> 0 | BW12: =+C12+I12+O12+AA12+AG12+U12+AM12+AS12+AY12+BE12+BK12+BQ12 -> 0 | BX12: =+D12+J12+P12+AB12+AH12+V12+AN12+AT12+AZ12+BF12+BL12+BR12 -> 0 | BY12: =SUM(BW12:BX12) -> 0 | BZ12: =+F12+L12+R12+AD12+AJ12+X12+AP12+AV12+BB12+BH12+BN12+BT12 -> 0 | CA12: =+G12+M12+S12+AE12+AK12+Y12+AQ12+AW12+BC12+BI12+BO12+BU12 -> 0 | CB12: =SUM(BZ12:CA12) -> 0
B13: в т.ч. внутрішньогрупові доходи від реалізації продукції | C13: ='[5]ПП ВДГ'!C13+'[5]Корсак Л.Р.'!C13+'[5]Корсак В.І.'!C13+[5]Конякіна!C13 -> 0 | D13: ='[5]ПП ВДГ'!D13+'[5]Корсак Л.Р.'!D13+'[5]Корсак В.І.'!D13+[5]Конякіна!D13 -> 0 | E13: =SUM(C13:D13) -> 0 | F13: ='Солар Вест'!F13+Будник!F13 -> 0 | G13: ='Солар Вест'!G13+Будник!G13 -> 0 | H13: =SUM(F13:G13) -> 0 | I13: ='[5]ПП ВДГ'!I13+'[5]Корсак Л.Р.'!I13+'[5]Корсак В.І.'!I13+[5]Конякіна!I13 -> 0 | J13: ='[5]ПП ВДГ'!J13+'[5]Корсак Л.Р.'!J13+'[5]Корсак В.І.'!J13+[5]Конякіна!J13 -> 0 | K13: =SUM(I13:J13) -> 0 | L13: ='Солар Вест'!L13+Будник!L13 -> 0 | M13: ='Солар Вест'!M13+Будник!M13 -> 0 | N13: =SUM(L13:M13) -> 0 | O13: ='[5]ПП ВДГ'!O13+'[5]Корсак Л.Р.'!O13+'[5]Корсак В.І.'!O13+[5]Конякіна!O13 -> 0 | P13: ='[5]ПП ВДГ'!P13+'[5]Корсак Л.Р.'!P13+'[5]Корсак В.І.'!P13+[5]Конякіна!P13 -> 0 | Q13: =SUM(O13:P13) -> 0 | R13: ='Солар Вест'!R13+Будник!R13 -> 0 | S13: ='Солар Вест'!S13+Будник!S13 -> 0 | T13: =SUM(R13:S13) -> 0 | U13: ='[5]ПП ВДГ'!U13+'[5]Корсак Л.Р.'!U13+'[5]Корсак В.І.'!U13+[5]Конякіна!U13 -> 0 | V13: ='[5]ПП ВДГ'!V13+'[5]Корсак Л.Р.'!V13+'[5]Корсак В.І.'!V13+[5]Конякіна!V13 -> 0 | W13: =SUM(U13:V13) -> 0 | X13: ='Солар Вест'!X13+Будник!X13 -> 0 | Y13: ='Солар Вест'!Y13+Будник!Y13 -> 0 | Z13: =SUM(X13:Y13) -> 0 | AA13: ='[5]ПП ВДГ'!AA13+'[5]Корсак Л.Р.'!AA13+'[5]Корсак В.І.'!AA13+[5]Конякіна!AA13 -> 0 | AB13: ='[5]ПП ВДГ'!AB13+'[5]Корсак Л.Р.'!AB13+'[5]Корсак В.І.'!AB13+[5]Конякіна!AB13 -> 0 | AC13: =SUM(AA13:AB13) -> 0 | AD13: ='Солар Вест'!AD13+Будник!AD13 -> 0 | AE13: ='Солар Вест'!AE13+Будник!AE13 -> 0 | AF13: =SUM(AD13:AE13) -> 0 | AG13: ='[5]ПП ВДГ'!AG13+'[5]Корсак Л.Р.'!AG13+'[5]Корсак В.І.'!AG13+[5]Конякіна!AG13 -> 0 | AH13: ='[5]ПП ВДГ'!AH13+'[5]Корсак Л.Р.'!AH13+'[5]Корсак В.І.'!AH13+[5]Конякіна!AH13 -> 0 | AI13: =SUM(AG13:AH13) -> 0 | AJ13: ='Солар Вест'!AJ13+Будник!AJ13 -> 0 | AK13: ='Солар Вест'!AK13+Будник!AK13 -> 0 | AL13: =SUM(AJ13:AK13) -> 0 | AM13: ='[5]ПП ВДГ'!AM13+'[5]Корсак Л.Р.'!AM13+'[5]Корсак В.І.'!AM13+[5]Конякіна!AM13 -> 0 | AN13: ='[5]ПП ВДГ'!AN13+'[5]Корсак Л.Р.'!AN13+'[5]Корсак В.І.'!AN13+[5]Конякіна!AN13 -> 0 | AO13: =SUM(AM13:AN13) -> 0 | AP13: ='Солар Вест'!AP13+Будник!AP13 -> 0 | AQ13: ='Солар Вест'!AQ13+Будник!AQ13 -> 0 | AR13: =SUM(AP13:AQ13) -> 0 | AS13: ='[5]ПП ВДГ'!AS13+'[5]Корсак Л.Р.'!AS13+'[5]Корсак В.І.'!AS13+[5]Конякіна!AS13 -> 0 | AT13: ='[5]ПП ВДГ'!AT13+'[5]Корсак Л.Р.'!AT13+'[5]Корсак В.І.'!AT13+[5]Конякіна!AT13 -> 0 | AU13: =SUM(AS13:AT13) -> 0 | AV13: ='Солар Вест'!AV13+Будник!AV13 -> 0 | AW13: ='Солар Вест'!AW13+Будник!AW13 -> 0 | AX13: =SUM(AV13:AW13) -> 0 | AY13: ='[5]ПП ВДГ'!AY13+'[5]Корсак Л.Р.'!AY13+'[5]Корсак В.І.'!AY13+[5]Конякіна!AY13 -> 0 | AZ13: ='[5]ПП ВДГ'!AZ13+'[5]Корсак Л.Р.'!AZ13+'[5]Корсак В.І.'!AZ13+[5]Конякіна!AZ13 -> 0 | BA13: =SUM(AY13:AZ13) -> 0 | BB13: ='Солар Вест'!BB13+Будник!BB13 -> 0 | BC13: ='Солар Вест'!BC13+Будник!BC13 -> 0 | BD13: =SUM(BB13:BC13) -> 0 | BE13: ='Солар Вест'!BE13+Будник!BE13 -> 0 | BF13: ='Солар Вест'!BF13+Будник!BF13 -> 0 | BG13: =SUM(BE13:BF13) -> 0 | BH13: ='Солар Вест'!BH13+Будник!BH13 -> 0 | BI13: ='Солар Вест'!BI13+Будник!BI13 -> 0 | BJ13: =SUM(BH13:BI13) -> 0 | BK13: ='[5]ПП ВДГ'!BK13+'[5]Корсак Л.Р.'!BK13+'[5]Корсак В.І.'!BK13+[5]Конякіна!BK13 -> 0 | BL13: ='[5]ПП ВДГ'!BL13+'[5]Корсак Л.Р.'!BL13+'[5]Корсак В.І.'!BL13+[5]Конякіна!BL13 -> 0 | BM13: =SUM(BK13:BL13) -> 0 | BN13: ='Солар Вест'!BN13+Будник!BN13 -> 0 | BO13: ='Солар Вест'!BO13+Будник!BO13 -> 0 | BP13: =SUM(BN13:BO13) -> 0 | BQ13: ='[5]ПП ВДГ'!BQ13+'[5]Корсак Л.Р.'!BQ13+'[5]Корсак В.І.'!BQ13+[5]Конякіна!BQ13 -> 0 | BR13: ='[5]ПП ВДГ'!BR13+'[5]Корсак Л.Р.'!BR13+'[5]Корсак В.І.'!BR13+[5]Конякіна!BR13 -> 0 | BS13: =SUM(BQ13:BR13) -> 0 | BT13: ='Солар Вест'!BT13+Будник!BT13 -> 0 | BU13: ='Солар Вест'!BU13+Будник!BU13 -> 0 | BV13: =SUM(BT13:BU13) -> 0 | BW13: =+C13+I13+O13+AA13+AG13+U13+AM13+AS13+AY13+BE13+BK13+BQ13 -> 0 | BX13: =+D13+J13+P13+AB13+AH13+V13+AN13+AT13+AZ13+BF13+BL13+BR13 -> 0 | BY13: =SUM(BW13:BX13) -> 0 | BZ13: =+F13+L13+R13+AD13+AJ13+X13+AP13+AV13+BB13+BH13+BN13+BT13 -> 0 | CA13: =+G13+M13+S13+AE13+AK13+Y13+AQ13+AW13+BC13+BI13+BO13+BU13 -> 0 | CB13: =SUM(BZ13:CA13) -> 0
A14: 112 | B14: Дохід від реалізації товарів | C14: ='[5]ПП ВДГ'!C14+'[5]Корсак Л.Р.'!C14+'[5]Корсак В.І.'!C14+[5]Конякіна!C14 -> 0 | D14: ='[5]ПП ВДГ'!D14+'[5]Корсак Л.Р.'!D14+'[5]Корсак В.І.'!D14+[5]Конякіна!D14 -> 0 | E14: =SUM(C14:D14) -> 0 | F14: ='Солар Вест'!F14+Будник!F14 -> 125791.1 | G14: ='Солар Вест'!G14+Будник!G14 -> 2810 | H14: =SUM(F14:G14) -> 128601.1 | I14: ='[5]ПП ВДГ'!I14+'[5]Корсак Л.Р.'!I14+'[5]Корсак В.І.'!I14+[5]Конякіна!I14 -> 0 | J14: ='[5]ПП ВДГ'!J14+'[5]Корсак Л.Р.'!J14+'[5]Корсак В.І.'!J14+[5]Конякіна!J14 -> 0 | K14: =SUM(I14:J14) -> 0 | L14: ='Солар Вест'!L14+Будник!L14 -> 157034.6 | M14: ='Солар Вест'!M14+Будник!M14 -> 3300 | N14: =SUM(L14:M14) -> 160334.6 | O14: ='[5]ПП ВДГ'!O14+'[5]Корсак Л.Р.'!O14+'[5]Корсак В.І.'!O14+[5]Конякіна!O14 -> 0 | P14: ='[5]ПП ВДГ'!P14+'[5]Корсак Л.Р.'!P14+'[5]Корсак В.І.'!P14+[5]Конякіна!P14 -> 0 | Q14: =SUM(O14:P14) -> 0 | R14: ='Солар Вест'!R14+Будник!R14 -> 2086265.6 | S14: ='Солар Вест'!S14+Будник!S14 -> 79400 | T14: =SUM(R14:S14) -> 2165665.5 | U14: ='[5]ПП ВДГ'!U14+'[5]Корсак Л.Р.'!U14+'[5]Корсак В.І.'!U14+[5]Конякіна!U14 -> 0 | V14: ='[5]ПП ВДГ'!V14+'[5]Корсак Л.Р.'!V14+'[5]Корсак В.І.'!V14+[5]Конякіна!V14 -> 0 | W14: =SUM(U14:V14) -> 0 | X14: ='Солар Вест'!X14+Будник!X14 -> 2535318.4 | Y14: ='Солар Вест'!Y14+Будник!Y14 -> 135358 | Z14: =SUM(X14:Y14) -> 2670676.4 | AA14: ='[5]ПП ВДГ'!AA14+'[5]Корсак Л.Р.'!AA14+'[5]Корсак В.І.'!AA14+[5]Конякіна!AA14 -> 0 | AB14: ='[5]ПП ВДГ'!AB14+'[5]Корсак Л.Р.'!AB14+'[5]Корсак В.І.'!AB14+[5]Конякіна!AB14 -> 0 | AC14: =SUM(AA14:AB14) -> 0 | AD14: ='Солар Вест'!AD14+Будник!AD14 -> 1074727.5 | AE14: ='Солар Вест'!AE14+Будник!AE14 -> 29910 | AF14: =SUM(AD14:AE14) -> 1104637.5 | AG14: ='[5]ПП ВДГ'!AG14+'[5]Корсак Л.Р.'!AG14+'[5]Корсак В.І.'!AG14+[5]Конякіна!AG14 -> 0 | AH14: ='[5]ПП ВДГ'!AH14+'[5]Корсак Л.Р.'!AH14+'[5]Корсак В.І.'!AH14+[5]Конякіна!AH14 -> 0 | AI14: =SUM(AG14:AH14) -> 0 | AJ14: ='Солар Вест'!AJ14+Будник!AJ14 -> 4236033.3 | AK14: ='Солар Вест'!AK14+Будник!AK14 -> 19150 | AL14: =SUM(AJ14:AK14) -> 4255183.3 | AM14: ='[5]ПП ВДГ'!AM14+'[5]Корсак Л.Р.'!AM14+'[5]Корсак В.І.'!AM14+[5]Конякіна!AM14 -> 0 | AN14: ='[5]ПП ВДГ'!AN14+'[5]Корсак Л.Р.'!AN14+'[5]Корсак В.І.'!AN14+[5]Конякіна!AN14 -> 0 | AO14: =SUM(AM14:AN14) -> 0 | AP14: ='Солар Вест'!AP14+Будник!AP14 -> 948545.59 | AQ14: ='Солар Вест'!AQ14+Будник!AQ14 -> 9375 | AR14: =SUM(AP14:AQ14) -> 957920.59 | AS14: ='[5]ПП ВДГ'!AS14+'[5]Корсак Л.Р.'!AS14+'[5]Корсак В.І.'!AS14+[5]Конякіна!AS14 -> 0 | AT14: ='[5]ПП ВДГ'!AT14+'[5]Корсак Л.Р.'!AT14+'[5]Корсак В.І.'!AT14+[5]Конякіна!AT14 -> 0 | AU14: =SUM(AS14:AT14) -> 0 | AV14: ='Солар Вест'!AV14+Будник!AV14 -> 264408.5 | AW14: ='Солар Вест'!AW14+Будник!AW14 -> 17302 | AX14: =SUM(AV14:AW14) -> 281710.5 | AY14: ='[5]ПП ВДГ'!AY14+'[5]Корсак Л.Р.'!AY14+'[5]Корсак В.І.'!AY14+[5]Конякіна!AY14 -> 0 | AZ14: ='[5]ПП ВДГ'!AZ14+'[5]Корсак Л.Р.'!AZ14+'[5]Корсак В.І.'!AZ14+[5]Конякіна!AZ14 -> 0 | BA14: =SUM(AY14:AZ14) -> 0 | BB14: ='Солар Вест'!BB14+Будник!BB14 -> 1162866.5 | BC14: ='Солар Вест'!BC14+Будник!BC14 -> 1920 | BD14: =SUM(BB14:BC14) -> 1164786.5 | BE14: ='Солар Вест'!BE14+Будник!BE14 -> 583567.42 | BF14: ='Солар Вест'!BF14+Будник!BF14 -> 140808 | BG14: =SUM(BE14:BF14) -> 724375.42 | BH14: ='Солар Вест'!BH14+Будник!BH14 -> 0 | BI14: ='Солар Вест'!BI14+Будник!BI14 -> 0 | BJ14: =SUM(BH14:BI14) -> 0 | BK14: ='[5]ПП ВДГ'!BK14+'[5]Корсак Л.Р.'!BK14+'[5]Корсак В.І.'!BK14+[5]Конякіна!BK14 -> 0 | BL14: ='[5]ПП ВДГ'!BL14+'[5]Корсак Л.Р.'!BL14+'[5]Корсак В.І.'!BL14+[5]Конякіна!BL14 -> 0 | BM14: =SUM(BK14:BL14) -> 0 | BN14: ='Солар Вест'!BN14+Будник!BN14 -> 0 | BO14: ='Солар Вест'!BO14+Будник!BO14 -> 0 | BP14: =SUM(BN14:BO14) -> 0 | BQ14: ='[5]ПП ВДГ'!BQ14+'[5]Корсак Л.Р.'!BQ14+'[5]Корсак В.І.'!BQ14+[5]Конякіна!BQ14 -> 0 | BR14: ='[5]ПП ВДГ'!BR14+'[5]Корсак Л.Р.'!BR14+'[5]Корсак В.І.'!BR14+[5]Конякіна!BR14 -> 0 | BS14: =SUM(BQ14:BR14) -> 0 | BT14: ='Солар Вест'!BT14+Будник!BT14 -> 0 | BU14: ='Солар Вест'!BU14+Будник!BU14 -> 0 | BV14: =SUM(BT14:BU14) -> 0 | BW14: =+C14+I14+O14+AA14+AG14+U14+AM14+AS14+AY14+BE14+BK14+BQ14 -> 583567.42 | BX14: =+D14+J14+P14+AB14+AH14+V14+AN14+AT14+AZ14+BF14+BL14+BR14 -> 140808 | BY14: =SUM(BW14:BX14) -> 724375.42 | BZ14: =+F14+L14+R14+AD14+AJ14+X14+AP14+AV14+BB14+BH14+BN14+BT14 -> 12590991 | CA14: =+G14+M14+S14+AE14+AK14+Y14+AQ14+AW14+BC14+BI14+BO14+BU14 -> 298525 | CB14: =SUM(BZ14:CA14) -> 12889516
B15: в т.ч. внутрішньогрупові доходи від реалізації товарів | C15: ='[5]ПП ВДГ'!C15+'[5]Корсак Л.Р.'!C15+'[5]Корсак В.І.'!C15+[5]Конякіна!C15 -> 0 | D15: ='[5]ПП ВДГ'!D15+'[5]Корсак Л.Р.'!D15+'[5]Корсак В.І.'!D15+[5]Конякіна!D15 -> 0 | E15: =SUM(C15:D15) -> 0 | F15: ='Солар Вест'!F15+Будник!F15 -> 0 | G15: ='Солар Вест'!G15+Будник!G15 -> 0 | H15: =SUM(F15:G15) -> 0 | I15: ='[5]ПП ВДГ'!I15+'[5]Корсак Л.Р.'!I15+'[5]Корсак В.І.'!I15+[5]Конякіна!I15 -> 0 | J15: ='[5]ПП ВДГ'!J15+'[5]Корсак Л.Р.'!J15+'[5]Корсак В.І.'!J15+[5]Конякіна!J15 -> 0 | K15: =SUM(I15:J15) -> 0 | L15: ='Солар Вест'!L15+Будник!L15 -> 0 | M15: ='Солар Вест'!M15+Будник!M15 -> 0 | N15: =SUM(L15:M15) -> 0 | O15: ='[5]ПП ВДГ'!O15+'[5]Корсак Л.Р.'!O15+'[5]Корсак В.І.'!O15+[5]Конякіна!O15 -> 0 | P15: ='[5]ПП ВДГ'!P15+'[5]Корсак Л.Р.'!P15+'[5]Корсак В.І.'!P15+[5]Конякіна!P15 -> 0 | Q15: =SUM(O15:P15) -> 0 | R15: ='Солар Вест'!R15+Будник!R15 -> 0 | S15: ='Солар Вест'!S15+Будник!S15 -> 0 | T15: =SUM(R15:S15) -> 0 | U15: ='[5]ПП ВДГ'!U15+'[5]Корсак Л.Р.'!U15+'[5]Корсак В.І.'!U15+[5]Конякіна!U15 -> 0 | V15: ='[5]ПП ВДГ'!V15+'[5]Корсак Л.Р.'!V15+'[5]Корсак В.І.'!V15+[5]Конякіна!V15 -> 0 | W15: =SUM(U15:V15) -> 0 | X15: ='Солар Вест'!X15+Будник!X15 -> 0 | Y15: ='Солар Вест'!Y15+Будник!Y15 -> 0 | Z15: =SUM(X15:Y15) -> 0 | AA15: ='[5]ПП ВДГ'!AA15+'[5]Корсак Л.Р.'!AA15+'[5]Корсак В.І.'!AA15+[5]Конякіна!AA15 -> 0 | AB15: ='[5]ПП ВДГ'!AB15+'[5]Корсак Л.Р.'!AB15+'[5]Корсак В.І.'!AB15+[5]Конякіна!AB15 -> 0 | AC15: =SUM(AA15:AB15) -> 0 | AD15: ='Солар Вест'!AD15+Будник!AD15 -> 0 | AE15: ='Солар Вест'!AE15+Будник!AE15 -> 0 | AF15: =SUM(AD15:AE15) -> 0 | AG15: ='[5]ПП ВДГ'!AG15+'[5]Корсак Л.Р.'!AG15+'[5]Корсак В.І.'!AG15+[5]Конякіна!AG15 -> 0 | AH15: ='[5]ПП ВДГ'!AH15+'[5]Корсак Л.Р.'!AH15+'[5]Корсак В.І.'!AH15+[5]Конякіна!AH15 -> 0 | AI15: =SUM(AG15:AH15) -> 0 | AJ15: ='Солар Вест'!AJ15+Будник!AJ15 -> 0 | AK15: ='Солар Вест'!AK15+Будник!AK15 -> 0 | AL15: =SUM(AJ15:AK15) -> 0 | AM15: ='[5]ПП ВДГ'!AM15+'[5]Корсак Л.Р.'!AM15+'[5]Корсак В.І.'!AM15+[5]Конякіна!AM15 -> 0 | AN15: ='[5]ПП ВДГ'!AN15+'[5]Корсак Л.Р.'!AN15+'[5]Корсак В.І.'!AN15+[5]Конякіна!AN15 -> 0 | AO15: =SUM(AM15:AN15) -> 0 | AP15: ='Солар Вест'!AP15+Будник!AP15 -> 0 | AQ15: ='Солар Вест'!AQ15+Будник!AQ15 -> 0 | AR15: =SUM(AP15:AQ15) -> 0 | AS15: ='[5]ПП ВДГ'!AS15+'[5]Корсак Л.Р.'!AS15+'[5]Корсак В.І.'!AS15+[5]Конякіна!AS15 -> 0 | AT15: ='[5]ПП ВДГ'!AT15+'[5]Корсак Л.Р.'!AT15+'[5]Корсак В.І.'!AT15+[5]Конякіна!AT15 -> 0 | AU15: =SUM(AS15:AT15) -> 0 | AV15: ='Солар Вест'!AV15+Будник!AV15 -> 0 | AW15: ='Солар Вест'!AW15+Будник!AW15 -> 0 | AX15: =SUM(AV15:AW15) -> 0 | AY15: ='[5]ПП ВДГ'!AY15+'[5]Корсак Л.Р.'!AY15+'[5]Корсак В.І.'!AY15+[5]Конякіна!AY15 -> 0 | AZ15: ='[5]ПП ВДГ'!AZ15+'[5]Корсак Л.Р.'!AZ15+'[5]Корсак В.І.'!AZ15+[5]Конякіна!AZ15 -> 0 | BA15: =SUM(AY15:AZ15) -> 0 | BB15: ='Солар Вест'!BB15+Будник!BB15 -> 0 | BC15: ='Солар Вест'!BC15+Будник!BC15 -> 0 | BD15: =SUM(BB15:BC15) -> 0 | BE15: ='Солар Вест'!BE15+Будник!BE15 -> 0 | BF15: ='Солар Вест'!BF15+Будник!BF15 -> 0 | BG15: =SUM(BE15:BF15) -> 0 | BH15: ='Солар Вест'!BH15+Будник!BH15 -> 0 | BI15: ='Солар Вест'!BI15+Будник!BI15 -> 0 | BJ15: =SUM(BH15:BI15) -> 0 | BK15: ='[5]ПП ВДГ'!BK15+'[5]Корсак Л.Р.'!BK15+'[5]Корсак В.І.'!BK15+[5]Конякіна!BK15 -> 0 | BL15: ='[5]ПП ВДГ'!BL15+'[5]Корсак Л.Р.'!BL15+'[5]Корсак В.І.'!BL15+[5]Конякіна!BL15 -> 0 | BM15: =SUM(BK15:BL15) -> 0 | BN15: ='Солар Вест'!BN15+Будник!BN15 -> 0 | BO15: ='Солар Вест'!BO15+Будник!BO15 -> 0 | BP15: =SUM(BN15:BO15) -> 0 | BQ15: ='[5]ПП ВДГ'!BQ15+'[5]Корсак Л.Р.'!BQ15+'[5]Корсак В.І.'!BQ15+[5]Конякіна!BQ15 -> 0 | BR15: ='[5]ПП ВДГ'!BR15+'[5]Корсак Л.Р.'!BR15+'[5]Корсак В.І.'!BR15+[5]Конякіна!BR15 -> 0 | BS15: =SUM(BQ15:BR15) -> 0 | BT15: ='Солар Вест'!BT15+Будник!BT15 -> 0 | BU15: ='Солар Вест'!BU15+Будник!BU15 -> 0 | BV15: =SUM(BT15:BU15) -> 0 | BW15: =+C15+I15+O15+AA15+AG15+U15+AM15+AS15+AY15+BE15+BK15+BQ15 -> 0 | BX15: =+D15+J15+P15+AB15+AH15+V15+AN15+AT15+AZ15+BF15+BL15+BR15 -> 0 | BY15: =SUM(BW15:BX15) -> 0 | BZ15: =+F15+L15+R15+AD15+AJ15+X15+AP15+AV15+BB15+BH15+BN15+BT15 -> 0 | CA15: =+G15+M15+S15+AE15+AK15+Y15+AQ15+AW15+BC15+BI15+BO15+BU15 -> 0 | CB15: =SUM(BZ15:CA15) -> 0
A16: 113 | B16: Дохід від реалізації послуг | C16: ='[5]ПП ВДГ'!C16+'[5]Корсак Л.Р.'!C16+'[5]Корсак В.І.'!C16+[5]Конякіна!C16 -> 0 | D16: ='[5]ПП ВДГ'!D16+'[5]Корсак Л.Р.'!D16+'[5]Корсак В.І.'!D16+[5]Конякіна!D16 -> 0 | E16: =SUM(C16:D16) -> 0 | F16: ='Солар Вест'!F16+Будник!F16 -> 0 | G16: ='Солар Вест'!G16+Будник!G16 -> 229400 | H16: =SUM(F16:G16) -> 229400 | I16: ='[5]ПП ВДГ'!I16+'[5]Корсак Л.Р.'!I16+'[5]Корсак В.І.'!I16+[5]Конякіна!I16 -> 0 | J16: ='[5]ПП ВДГ'!J16+'[5]Корсак Л.Р.'!J16+'[5]Корсак В.І.'!J16+[5]Конякіна!J16 -> 0 | K16: =SUM(I16:J16) -> 0 | L16: ='Солар Вест'!L16+Будник!L16 -> 0 | M16: ='Солар Вест'!M16+Будник!M16 -> 169100 | N16: =SUM(L16:M16) -> 169100 | O16: ='[5]ПП ВДГ'!O16+'[5]Корсак Л.Р.'!O16+'[5]Корсак В.І.'!O16+[5]Конякіна!O16 -> 0 | P16: ='[5]ПП ВДГ'!P16+'[5]Корсак Л.Р.'!P16+'[5]Корсак В.І.'!P16+[5]Конякіна!P16 -> 0 | Q16: =SUM(O16:P16) -> 0 | R16: ='Солар Вест'!R16+Будник!R16 -> 0 | S16: ='Солар Вест'!S16+Будник!S16 -> 188610 | T16: =SUM(R16:S16) -> 188610 | U16: ='[5]ПП ВДГ'!U16+'[5]Корсак Л.Р.'!U16+'[5]Корсак В.І.'!U16+[5]Конякіна!U16 -> 0 | V16: ='[5]ПП ВДГ'!V16+'[5]Корсак Л.Р.'!V16+'[5]Корсак В.І.'!V16+[5]Конякіна!V16 -> 0 | W16: =SUM(U16:V16) -> 0 | X16: ='Солар Вест'!X16+Будник!X16 -> 0 | Y16: ='Солар Вест'!Y16+Будник!Y16 -> 410000 | Z16: =SUM(X16:Y16) -> 410000 | AA16: ='[5]ПП ВДГ'!AA16+'[5]Корсак Л.Р.'!AA16+'[5]Корсак В.І.'!AA16+[5]Конякіна!AA16 -> 0 | AB16: ='[5]ПП ВДГ'!AB16+'[5]Корсак Л.Р.'!AB16+'[5]Корсак В.І.'!AB16+[5]Конякіна!AB16 -> 0 | AC16: =SUM(AA16:AB16) -> 0 | AD16: ='Солар Вест'!AD16+Будник!AD16 -> 0 | AE16: ='Солар Вест'!AE16+Будник!AE16 -> 687620 | AF16: =SUM(AD16:AE16) -> 687620 | AG16: ='[5]ПП ВДГ'!AG16+'[5]Корсак Л.Р.'!AG16+'[5]Корсак В.І.'!AG16+[5]Конякіна!AG16 -> 0 | AH16: ='[5]ПП ВДГ'!AH16+'[5]Корсак Л.Р.'!AH16+'[5]Корсак В.І.'!AH16+[5]Конякіна!AH16 -> 0 | AI16: =SUM(AG16:AH16) -> 0 | AJ16: ='Солар Вест'!AJ16+Будник!AJ16 -> 62000 | AK16: ='Солар Вест'!AK16+Будник!AK16 -> 643228 | AL16: =SUM(AJ16:AK16) -> 705228 | AM16: ='[5]ПП ВДГ'!AM16+'[5]Корсак Л.Р.'!AM16+'[5]Корсак В.І.'!AM16+[5]Конякіна!AM16 -> 0 | AN16: ='[5]ПП ВДГ'!AN16+'[5]Корсак Л.Р.'!AN16+'[5]Корсак В.І.'!AN16+[5]Конякіна!AN16 -> 0 | AO16: =SUM(AM16:AN16) -> 0 | AP16: ='Солар Вест'!AP16+Будник!AP16 -> 56600 | AQ16: ='Солар Вест'!AQ16+Будник!AQ16 -> 222000 | AR16: =SUM(AP16:AQ16) -> 278600 | AS16: ='[5]ПП ВДГ'!AS16+'[5]Корсак Л.Р.'!AS16+'[5]Корсак В.І.'!AS16+[5]Конякіна!AS16 -> 0 | AT16: ='[5]ПП ВДГ'!AT16+'[5]Корсак Л.Р.'!AT16+'[5]Корсак В.І.'!AT16+[5]Конякіна!AT16 -> 0 | AU16: =SUM(AS16:AT16) -> 0 | AV16: ='Солар Вест'!AV16+Будник!AV16 -> 528700 | AW16: ='Солар Вест'!AW16+Будник!AW16 -> 282290 | AX16: =SUM(AV16:AW16) -> 810990 | AY16: ='[5]ПП ВДГ'!AY16+'[5]Корсак Л.Р.'!AY16+'[5]Корсак В.І.'!AY16+[5]Конякіна!AY16 -> 0 | AZ16: ='[5]ПП ВДГ'!AZ16+'[5]Корсак Л.Р.'!AZ16+'[5]Корсак В.І.'!AZ16+[5]Конякіна!AZ16 -> 0 | BA16: =SUM(AY16:AZ16) -> 0 | BB16: ='Солар Вест'!BB16+Будник!BB16 -> 216700 | BC16: ='Солар Вест'!BC16+Будник!BC16 -> 283290 | BD16: =SUM(BB16:BC16) -> 499990 | BE16: ='Солар Вест'!BE16+Будник!BE16 -> 0 | BF16: ='Солар Вест'!BF16+Будник!BF16 -> 268985 | BG16: =SUM(BE16:BF16) -> 268985 | BH16: ='Солар Вест'!BH16+Будник!BH16 -> 0 | BI16: ='Солар Вест'!BI16+Будник!BI16 -> 0 | BJ16: =SUM(BH16:BI16) -> 0 | BK16: ='[5]ПП ВДГ'!BK16+'[5]Корсак Л.Р.'!BK16+'[5]Корсак В.І.'!BK16+[5]Конякіна!BK16 -> 0 | BL16: ='[5]ПП ВДГ'!BL16+'[5]Корсак Л.Р.'!BL16+'[5]Корсак В.І.'!BL16+[5]Конякіна!BL16 -> 0 | BM16: =SUM(BK16:BL16) -> 0 | BN16: ='Солар Вест'!BN16+Будник!BN16 -> 0 | BO16: ='Солар Вест'!BO16+Будник!BO16 -> 0 | BP16: =SUM(BN16:BO16) -> 0 | BQ16: ='[5]ПП ВДГ'!BQ16+'[5]Корсак Л.Р.'!BQ16+'[5]Корсак В.І.'!BQ16+[5]Конякіна!BQ16 -> 0 | BR16: ='[5]ПП ВДГ'!BR16+'[5]Корсак Л.Р.'!BR16+'[5]Корсак В.І.'!BR16+[5]Конякіна!BR16 -> 0 | BS16: =SUM(BQ16:BR16) -> 0 | BT16: ='Солар Вест'!BT16+Будник!BT16 -> 0 | BU16: ='Солар Вест'!BU16+Будник!BU16 -> 0 | BV16: =SUM(BT16:BU16) -> 0 | BW16: =+C16+I16+O16+AA16+AG16+U16+AM16+AS16+AY16+BE16+BK16+BQ16 -> 0 | BX16: =+D16+J16+P16+AB16+AH16+V16+AN16+AT16+AZ16+BF16+BL16+BR16 -> 268985 | BY16: =SUM(BW16:BX16) -> 268985 | BZ16: =+F16+L16+R16+AD16+AJ16+X16+AP16+AV16+BB16+BH16+BN16+BT16 -> 864000 | CA16: =+G16+M16+S16+AE16+AK16+Y16+AQ16+AW16+BC16+BI16+BO16+BU16 -> 3115538 | CB16: =SUM(BZ16:CA16) -> 3979538
B17: в т.ч. внутрішньогрупові доходи від реалізації послуг | C17: ='[5]ПП ВДГ'!C17+'[5]Корсак Л.Р.'!C17+'[5]Корсак В.І.'!C17+[5]Конякіна!C17 -> 0 | D17: ='[5]ПП ВДГ'!D17+'[5]Корсак Л.Р.'!D17+'[5]Корсак В.І.'!D17+[5]Конякіна!D17 -> 0 | E17: =SUM(C17:D17) -> 0 | F17: ='Солар Вест'!F17+Будник!F17 -> 0 | G17: ='Солар Вест'!G17+Будник!G17 -> 0 | H17: =SUM(F17:G17) -> 0 | I17: ='[5]ПП ВДГ'!I17+'[5]Корсак Л.Р.'!I17+'[5]Корсак В.І.'!I17+[5]Конякіна!I17 -> 0 | J17: ='[5]ПП ВДГ'!J17+'[5]Корсак Л.Р.'!J17+'[5]Корсак В.І.'!J17+[5]Конякіна!J17 -> 0 | K17: =SUM(I17:J17) -> 0 | L17: ='Солар Вест'!L17+Будник!L17 -> 0 | M17: ='Солар Вест'!M17+Будник!M17 -> 0 | N17: =SUM(L17:M17) -> 0 | O17: ='[5]ПП ВДГ'!O17+'[5]Корсак Л.Р.'!O17+'[5]Корсак В.І.'!O17+[5]Конякіна!O17 -> 0 | P17: ='[5]ПП ВДГ'!P17+'[5]Корсак Л.Р.'!P17+'[5]Корсак В.І.'!P17+[5]Конякіна!P17 -> 0 | Q17: =SUM(O17:P17) -> 0 | R17: ='Солар Вест'!R17+Будник!R17 -> 0 | S17: ='Солар Вест'!S17+Будник!S17 -> 0 | T17: =SUM(R17:S17) -> 0 | U17: ='[5]ПП ВДГ'!U17+'[5]Корсак Л.Р.'!U17+'[5]Корсак В.І.'!U17+[5]Конякіна!U17 -> 0 | V17: ='[5]ПП ВДГ'!V17+'[5]Корсак Л.Р.'!V17+'[5]Корсак В.І.'!V17+[5]Конякіна!V17 -> 0 | W17: =SUM(U17:V17) -> 0 | X17: ='Солар Вест'!X17+Будник!X17 -> 0 | Y17: ='Солар Вест'!Y17+Будник!Y17 -> 0 | Z17: =SUM(X17:Y17) -> 0 | AA17: ='[5]ПП ВДГ'!AA17+'[5]Корсак Л.Р.'!AA17+'[5]Корсак В.І.'!AA17+[5]Конякіна!AA17 -> 0 | AB17: ='[5]ПП ВДГ'!AB17+'[5]Корсак Л.Р.'!AB17+'[5]Корсак В.І.'!AB17+[5]Конякіна!AB17 -> 0 | AC17: =SUM(AA17:AB17) -> 0 | AD17: ='Солар Вест'!AD17+Будник!AD17 -> 0 | AE17: ='Солар Вест'!AE17+Будник!AE17 -> 0 | AF17: =SUM(AD17:AE17) -> 0 | AG17: ='[5]ПП ВДГ'!AG17+'[5]Корсак Л.Р.'!AG17+'[5]Корсак В.І.'!AG17+[5]Конякіна!AG17 -> 0 | AH17: ='[5]ПП ВДГ'!AH17+'[5]Корсак Л.Р.'!AH17+'[5]Корсак В.І.'!AH17+[5]Конякіна!AH17 -> 0 | AI17: =SUM(AG17:AH17) -> 0 | AJ17: ='Солар Вест'!AJ17+Будник!AJ17 -> 0 | AK17: ='Солар Вест'!AK17+Будник!AK17 -> 0 | AL17: =SUM(AJ17:AK17) -> 0 | AM17: ='[5]ПП ВДГ'!AM17+'[5]Корсак Л.Р.'!AM17+'[5]Корсак В.І.'!AM17+[5]Конякіна!AM17 -> 0 | AN17: ='[5]ПП ВДГ'!AN17+'[5]Корсак Л.Р.'!AN17+'[5]Корсак В.І.'!AN17+[5]Конякіна!AN17 -> 0 | AO17: =SUM(AM17:AN17) -> 0 | AP17: ='Солар Вест'!AP17+Будник!AP17 -> 0 | AQ17: ='Солар Вест'!AQ17+Будник!AQ17 -> 0 | AR17: =SUM(AP17:AQ17) -> 0 | AS17: ='[5]ПП ВДГ'!AS17+'[5]Корсак Л.Р.'!AS17+'[5]Корсак В.І.'!AS17+[5]Конякіна!AS17 -> 0 | AT17: ='[5]ПП ВДГ'!AT17+'[5]Корсак Л.Р.'!AT17+'[5]Корсак В.І.'!AT17+[5]Конякіна!AT17 -> 0 | AU17: =SUM(AS17:AT17) -> 0 | AV17: ='Солар Вест'!AV17+Будник!AV17 -> 0 | AW17: ='Солар Вест'!AW17+Будник!AW17 -> 0 | AX17: =SUM(AV17:AW17) -> 0 | AY17: ='[5]ПП ВДГ'!AY17+'[5]Корсак Л.Р.'!AY17+'[5]Корсак В.І.'!AY17+[5]Конякіна!AY17 -> 0 | AZ17: ='[5]ПП ВДГ'!AZ17+'[5]Корсак Л.Р.'!AZ17+'[5]Корсак В.І.'!AZ17+[5]Конякіна!AZ17 -> 0 | BA17: =SUM(AY17:AZ17) -> 0 | BB17: ='Солар Вест'!BB17+Будник!BB17 -> 0 | BC17: ='Солар Вест'!BC17+Будник!BC17 -> 0 | BD17: =SUM(BB17:BC17) -> 0 | BE17: ='Солар Вест'!BE17+Будник!BE17 -> 0 | BF17: ='Солар Вест'!BF17+Будник!BF17 -> 0 | BG17: =SUM(BE17:BF17) -> 0 | BH17: ='Солар Вест'!BH17+Будник!BH17 -> 0 | BI17: ='Солар Вест'!BI17+Будник!BI17 -> 0 | BJ17: =SUM(BH17:BI17) -> 0 | BK17: ='[5]ПП ВДГ'!BK17+'[5]Корсак Л.Р.'!BK17+'[5]Корсак В.І.'!BK17+[5]Конякіна!BK17 -> 0 | BL17: ='[5]ПП ВДГ'!BL17+'[5]Корсак Л.Р.'!BL17+'[5]Корсак В.І.'!BL17+[5]Конякіна!BL17 -> 0 | BM17: =SUM(BK17:BL17) -> 0 | BN17: ='Солар Вест'!BN17+Будник!BN17 -> 0 | BO17: ='Солар Вест'!BO17+Будник!BO17 -> 0 | BP17: =SUM(BN17:BO17) -> 0 | BQ17: ='[5]ПП ВДГ'!BQ17+'[5]Корсак Л.Р.'!BQ17+'[5]Корсак В.І.'!BQ17+[5]Конякіна!BQ17 -> 0 | BR17: ='[5]ПП ВДГ'!BR17+'[5]Корсак Л.Р.'!BR17+'[5]Корсак В.І.'!BR17+[5]Конякіна!BR17 -> 0 | BS17: =SUM(BQ17:BR17) -> 0 | BT17: ='Солар Вест'!BT17+Будник!BT17 -> 0 | BU17: ='Солар Вест'!BU17+Будник!BU17 -> 0 | BV17: =SUM(BT17:BU17) -> 0 | BW17: =+C17+I17+O17+AA17+AG17+U17+AM17+AS17+AY17+BE17+BK17+BQ17 -> 0 | BX17: =+D17+J17+P17+AB17+AH17+V17+AN17+AT17+AZ17+BF17+BL17+BR17 -> 0 | BY17: =SUM(BW17:BX17) -> 0 | BZ17: =+F17+L17+R17+AD17+AJ17+X17+AP17+AV17+BB17+BH17+BN17+BT17 -> 0 | CA17: =+G17+M17+S17+AE17+AK17+Y17+AQ17+AW17+BC17+BI17+BO17+BU17 -> 0 | CB17: =SUM(BZ17:CA17) -> 0
A18: 114 | B18: Дохід від оренди зовнішнім контрагентам | C18: ='[5]ПП ВДГ'!C18+'[5]Корсак Л.Р.'!C18+'[5]Корсак В.І.'!C18+[5]Конякіна!C18 -> 175000 | D18: ='[5]ПП ВДГ'!D18+'[5]Корсак Л.Р.'!D18+'[5]Корсак В.І.'!D18+[5]Конякіна!D18 -> 191000 | E18: =SUM(C18:D18) -> 366000 | F18: ='Солар Вест'!F18+Будник!F18 -> 0 | G18: ='Солар Вест'!G18+Будник!G18 -> 0 | H18: =SUM(F18:G18) -> 0 | I18: ='[5]ПП ВДГ'!I18+'[5]Корсак Л.Р.'!I18+'[5]Корсак В.І.'!I18+[5]Конякіна!I18 -> 175000 | J18: ='[5]ПП ВДГ'!J18+'[5]Корсак Л.Р.'!J18+'[5]Корсак В.І.'!J18+[5]Конякіна!J18 -> 191000 | K18: =SUM(I18:J18) -> 366000 | L18: ='Солар Вест'!L18+Будник!L18 -> 0 | M18: ='Солар Вест'!M18+Будник!M18 -> 0 | N18: =SUM(L18:M18) -> 0 | O18: ='[5]ПП ВДГ'!O18+'[5]Корсак Л.Р.'!O18+'[5]Корсак В.І.'!O18+[5]Конякіна!O18 -> 175000 | P18: ='[5]ПП ВДГ'!P18+'[5]Корсак Л.Р.'!P18+'[5]Корсак В.І.'!P18+[5]Конякіна!P18 -> 191000 | Q18: =SUM(O18:P18) -> 366000 | R18: ='Солар Вест'!R18+Будник!R18 -> 0 | S18: ='Солар Вест'!S18+Будник!S18 -> 0 | T18: =SUM(R18:S18) -> 0 | U18: ='[5]ПП ВДГ'!U18+'[5]Корсак Л.Р.'!U18+'[5]Корсак В.І.'!U18+[5]Конякіна!U18 -> 270000 | V18: ='[5]ПП ВДГ'!V18+'[5]Корсак Л.Р.'!V18+'[5]Корсак В.І.'!V18+[5]Конякіна!V18 -> 97000 | W18: =SUM(U18:V18) -> 367000 | X18: ='Солар Вест'!X18+Будник!X18 -> 0 | Y18: ='Солар Вест'!Y18+Будник!Y18 -> 0 | Z18: =SUM(X18:Y18) -> 0 | AA18: ='[5]ПП ВДГ'!AA18+'[5]Корсак Л.Р.'!AA18+'[5]Корсак В.І.'!AA18+[5]Конякіна!AA18 -> 175000 | AB18: ='[5]ПП ВДГ'!AB18+'[5]Корсак Л.Р.'!AB18+'[5]Корсак В.І.'!AB18+[5]Конякіна!AB18 -> 191000 | AC18: =SUM(AA18:AB18) -> 366000 | AD18: ='Солар Вест'!AD18+Будник!AD18 -> 0 | AE18: ='Солар Вест'!AE18+Будник!AE18 -> 0 | AF18: =SUM(AD18:AE18) -> 0 | AG18: ='[5]ПП ВДГ'!AG18+'[5]Корсак Л.Р.'!AG18+'[5]Корсак В.І.'!AG18+[5]Конякіна!AG18 -> 180000 | AH18: ='[5]ПП ВДГ'!AH18+'[5]Корсак Л.Р.'!AH18+'[5]Корсак В.І.'!AH18+[5]Конякіна!AH18 -> 199000 | AI18: =SUM(AG18:AH18) -> 379000 | AJ18: ='Солар Вест'!AJ18+Будник!AJ18 -> 0 | AK18: ='Солар Вест'!AK18+Будник!AK18 -> 0 | AL18: =SUM(AJ18:AK18) -> 0 | AM18: ='[5]ПП ВДГ'!AM18+'[5]Корсак Л.Р.'!AM18+'[5]Корсак В.І.'!AM18+[5]Конякіна!AM18 -> 175000 | AN18: ='[5]ПП ВДГ'!AN18+'[5]Корсак Л.Р.'!AN18+'[5]Корсак В.І.'!AN18+[5]Конякіна!AN18 -> 194000 | AO18: =SUM(AM18:AN18) -> 369000 | AP18: ='Солар Вест'!AP18+Будник!AP18 -> 0 | AQ18: ='Солар Вест'!AQ18+Будник!AQ18 -> 0 | AR18: =SUM(AP18:AQ18) -> 0 | AS18: ='[5]ПП ВДГ'!AS18+'[5]Корсак Л.Р.'!AS18+'[5]Корсак В.І.'!AS18+[5]Конякіна!AS18 -> 175000 | AT18: ='[5]ПП ВДГ'!AT18+'[5]Корсак Л.Р.'!AT18+'[5]Корсак В.І.'!AT18+[5]Конякіна!AT18 -> 191000 | AU18: =SUM(AS18:AT18) -> 366000 | AV18: ='Солар Вест'!AV18+Будник!AV18 -> 0 | AW18: ='Солар Вест'!AW18+Будник!AW18 -> 0 | AX18: =SUM(AV18:AW18) -> 0 | AY18: ='[5]ПП ВДГ'!AY18+'[5]Корсак Л.Р.'!AY18+'[5]Корсак В.І.'!AY18+[5]Конякіна!AY18 -> 175000 | AZ18: ='[5]ПП ВДГ'!AZ18+'[5]Корсак Л.Р.'!AZ18+'[5]Корсак В.І.'!AZ18+[5]Конякіна!AZ18 -> 191000 | BA18: =SUM(AY18:AZ18) -> 366000 | BB18: ='Солар Вест'!BB18+Будник!BB18 -> 0 | BC18: ='Солар Вест'!BC18+Будник!BC18 -> 0 | BD18: =SUM(BB18:BC18) -> 0 | BE18: ='Солар Вест'!BE18+Будник!BE18 -> 0 | BF18: ='Солар Вест'!BF18+Будник!BF18 -> 0 | BG18: =SUM(BE18:BF18) -> 0 | BH18: ='Солар Вест'!BH18+Будник!BH18 -> 0 | BI18: ='Солар Вест'!BI18+Будник!BI18 -> 0 | BJ18: =SUM(BH18:BI18) -> 0 | BK18: ='[5]ПП ВДГ'!BK18+'[5]Корсак Л.Р.'!BK18+'[5]Корсак В.І.'!BK18+[5]Конякіна!BK18 -> 175000 | BL18: ='[5]ПП ВДГ'!BL18+'[5]Корсак Л.Р.'!BL18+'[5]Корсак В.І.'!BL18+[5]Конякіна!BL18 -> 183000 | BM18: =SUM(BK18:BL18) -> 358000 | BN18: ='Солар Вест'!BN18+Будник!BN18 -> 0 | BO18: ='Солар Вест'!BO18+Будник!BO18 -> 0 | BP18: =SUM(BN18:BO18) -> 0 | BQ18: ='[5]ПП ВДГ'!BQ18+'[5]Корсак Л.Р.'!BQ18+'[5]Корсак В.І.'!BQ18+[5]Конякіна!BQ18 -> 235000 | BR18: ='[5]ПП ВДГ'!BR18+'[5]Корсак Л.Р.'!BR18+'[5]Корсак В.І.'!BR18+[5]Конякіна!BR18 -> 135000 | BS18: =SUM(BQ18:BR18) -> 370000 | BT18: ='Солар Вест'!BT18+Будник!BT18 -> 0 | BU18: ='Солар Вест'!BU18+Будник!BU18 -> 0 | BV18: =SUM(BT18:BU18) -> 0 | BW18: =+C18+I18+O18+AA18+AG18+U18+AM18+AS18+AY18+BE18+BK18+BQ18 -> 2085000 | BX18: =+D18+J18+P18+AB18+AH18+V18+AN18+AT18+AZ18+BF18+BL18+BR18 -> 1954000 | BY18: =SUM(BW18:BX18) -> 4039000 | BZ18: =+F18+L18+R18+AD18+AJ18+X18+AP18+AV18+BB18+BH18+BN18+BT18 -> 0 | CA18: =+G18+M18+S18+AE18+AK18+Y18+AQ18+AW18+BC18+BI18+BO18+BU18 -> 0 | CB18: =SUM(BZ18:CA18) -> 0
B19: в т.ч. внутрішньогруповий дохід від оренди | C19: ='[5]ПП ВДГ'!C19+'[5]Корсак Л.Р.'!C19+'[5]Корсак В.І.'!C19+[5]Конякіна!C19 -> 115000 | D19: ='[5]ПП ВДГ'!D19+'[5]Корсак Л.Р.'!D19+'[5]Корсак В.І.'!D19+[5]Конякіна!D19 -> 190000 | E19: =SUM(C19:D19) -> 305000 | F19: ='Солар Вест'!F19+Будник!F19 -> 0 | G19: ='Солар Вест'!G19+Будник!G19 -> 0 | H19: =SUM(F19:G19) -> 0 | I19: ='[5]ПП ВДГ'!I19+'[5]Корсак Л.Р.'!I19+'[5]Корсак В.І.'!I19+[5]Конякіна!I19 -> 115000 | J19: ='[5]ПП ВДГ'!J19+'[5]Корсак Л.Р.'!J19+'[5]Корсак В.І.'!J19+[5]Конякіна!J19 -> 190000 | K19: =SUM(I19:J19) -> 305000 | L19: ='Солар Вест'!L19+Будник!L19 -> 0 | M19: ='Солар Вест'!M19+Будник!M19 -> 0 | N19: =SUM(L19:M19) -> 0 | O19: ='[5]ПП ВДГ'!O19+'[5]Корсак Л.Р.'!O19+'[5]Корсак В.І.'!O19+[5]Конякіна!O19 -> 115000 | P19: ='[5]ПП ВДГ'!P19+'[5]Корсак Л.Р.'!P19+'[5]Корсак В.І.'!P19+[5]Конякіна!P19 -> 190000 | Q19: =SUM(O19:P19) -> 305000 | R19: ='Солар Вест'!R19+Будник!R19 -> 0 | S19: ='Солар Вест'!S19+Будник!S19 -> 0 | T19: =SUM(R19:S19) -> 0 | U19: ='[5]ПП ВДГ'!U19+'[5]Корсак Л.Р.'!U19+'[5]Корсак В.І.'!U19+[5]Конякіна!U19 -> 120000 | V19: ='[5]ПП ВДГ'!V19+'[5]Корсак Л.Р.'!V19+'[5]Корсак В.І.'!V19+[5]Конякіна!V19 -> 97000 | W19: =SUM(U19:V19) -> 217000 | X19: ='Солар Вест'!X19+Будник!X19 -> 0 | Y19: ='Солар Вест'!Y19+Будник!Y19 -> 0 | Z19: =SUM(X19:Y19) -> 0 | AA19: ='[5]ПП ВДГ'!AA19+'[5]Корсак Л.Р.'!AA19+'[5]Корсак В.І.'!AA19+[5]Конякіна!AA19 -> 115000 | AB19: ='[5]ПП ВДГ'!AB19+'[5]Корсак Л.Р.'!AB19+'[5]Корсак В.І.'!AB19+[5]Конякіна!AB19 -> 190000 | AC19: =SUM(AA19:AB19) -> 305000 | AD19: ='Солар Вест'!AD19+Будник!AD19 -> 0 | AE19: ='Солар Вест'!AE19+Будник!AE19 -> 0 | AF19: =SUM(AD19:AE19) -> 0 | AG19: ='[5]ПП ВДГ'!AG19+'[5]Корсак Л.Р.'!AG19+'[5]Корсак В.І.'!AG19+[5]Конякіна!AG19 -> 70000 | AH19: ='[5]ПП ВДГ'!AH19+'[5]Корсак Л.Р.'!AH19+'[5]Корсак В.І.'!AH19+[5]Конякіна!AH19 -> 197000 | AI19: =SUM(AG19:AH19) -> 267000 | AJ19: ='Солар Вест'!AJ19+Будник!AJ19 -> 0 | AK19: ='Солар Вест'!AK19+Будник!AK19 -> 0 | AL19: =SUM(AJ19:AK19) -> 0 | AM19: ='[5]ПП ВДГ'!AM19+'[5]Корсак Л.Р.'!AM19+'[5]Корсак В.І.'!AM19+[5]Конякіна!AM19 -> 65000 | AN19: ='[5]ПП ВДГ'!AN19+'[5]Корсак Л.Р.'!AN19+'[5]Корсак В.І.'!AN19+[5]Конякіна!AN19 -> 194000 | AO19: =SUM(AM19:AN19) -> 259000 | AP19: ='Солар Вест'!AP19+Будник!AP19 -> 0 | AQ19: ='Солар Вест'!AQ19+Будник!AQ19 -> 0 | AR19: =SUM(AP19:AQ19) -> 0 | AS19: ='[5]ПП ВДГ'!AS19+'[5]Корсак Л.Р.'!AS19+'[5]Корсак В.І.'!AS19+[5]Конякіна!AS19 -> 115000 | AT19: ='[5]ПП ВДГ'!AT19+'[5]Корсак Л.Р.'!AT19+'[5]Корсак В.І.'!AT19+[5]Конякіна!AT19 -> 190000 | AU19: =SUM(AS19:AT19) -> 305000 | AV19: ='Солар Вест'!AV19+Будник!AV19 -> 0 | AW19: ='Солар Вест'!AW19+Будник!AW19 -> 0 | AX19: =SUM(AV19:AW19) -> 0 | AY19: ='[5]ПП ВДГ'!AY19+'[5]Корсак Л.Р.'!AY19+'[5]Корсак В.І.'!AY19+[5]Конякіна!AY19 -> 115000 | AZ19: ='[5]ПП ВДГ'!AZ19+'[5]Корсак Л.Р.'!AZ19+'[5]Корсак В.І.'!AZ19+[5]Конякіна!AZ19 -> 190000 | BA19: =SUM(AY19:AZ19) -> 305000 | BB19: ='Солар Вест'!BB19+Будник!BB19 -> 0 | BC19: ='Солар Вест'!BC19+Будник!BC19 -> 0 | BD19: =SUM(BB19:BC19) -> 0 | BE19: ='Солар Вест'!BE19+Будник!BE19 -> 0 | BF19: ='Солар Вест'!BF19+Будник!BF19 -> 0 | BG19: =SUM(BE19:BF19) -> 0 | BH19: ='Солар Вест'!BH19+Будник!BH19 -> 0 | BI19: ='Солар Вест'!BI19+Будник!BI19 -> 0 | BJ19: =SUM(BH19:BI19) -> 0 | BK19: ='[5]ПП ВДГ'!BK19+'[5]Корсак Л.Р.'!BK19+'[5]Корсак В.І.'!BK19+[5]Конякіна!BK19 -> 66000 | BL19: ='[5]ПП ВДГ'!BL19+'[5]Корсак Л.Р.'!BL19+'[5]Корсак В.І.'!BL19+[5]Конякіна!BL19 -> 183000 | BM19: =SUM(BK19:BL19) -> 249000 | BN19: ='Солар Вест'!BN19+Будник!BN19 -> 0 | BO19: ='Солар Вест'!BO19+Будник!BO19 -> 0 | BP19: =SUM(BN19:BO19) -> 0 | BQ19: ='[5]ПП ВДГ'!BQ19+'[5]Корсак Л.Р.'!BQ19+'[5]Корсак В.І.'!BQ19+[5]Конякіна!BQ19 -> 135000 | BR19: ='[5]ПП ВДГ'!BR19+'[5]Корсак Л.Р.'!BR19+'[5]Корсак В.І.'!BR19+[5]Конякіна!BR19 -> 133000 | BS19: =SUM(BQ19:BR19) -> 268000 | BT19: ='Солар Вест'!BT19+Будник!BT19 -> 0 | BU19: ='Солар Вест'!BU19+Будник!BU19 -> 0 | BV19: =SUM(BT19:BU19) -> 0 | BW19: =+C19+I19+O19+AA19+AG19+U19+AM19+AS19+AY19+BE19+BK19+BQ19 -> 1146000 | BX19: =+D19+J19+P19+AB19+AH19+V19+AN19+AT19+AZ19+BF19+BL19+BR19 -> 1944000 | BY19: =SUM(BW19:BX19) -> 3090000 | BZ19: =+F19+L19+R19+AD19+AJ19+X19+AP19+AV19+BB19+BH19+BN19+BT19 -> 0 | CA19: =+G19+M19+S19+AE19+AK19+Y19+AQ19+AW19+BC19+BI19+BO19+BU19 -> 0 | CB19: =SUM(BZ19:CA19) -> 0
A20: 115 | B20: Інший дохід | C20: ='[5]ПП ВДГ'!C20+'[5]Корсак Л.Р.'!C20+'[5]Корсак В.І.'!C20+[5]Конякіна!C20 -> 0 | D20: ='[5]ПП ВДГ'!D20+'[5]Корсак Л.Р.'!D20+'[5]Корсак В.І.'!D20+[5]Конякіна!D20 -> 0 | E20: =SUM(C20:D20) -> 0 | F20: ='Солар Вест'!F20+Будник!F20 -> 0 | G20: ='Солар Вест'!G20+Будник!G20 -> 0 | H20: =SUM(F20:G20) -> 0 | I20: ='[5]ПП ВДГ'!I20+'[5]Корсак Л.Р.'!I20+'[5]Корсак В.І.'!I20+[5]Конякіна!I20 -> 0 | J20: ='[5]ПП ВДГ'!J20+'[5]Корсак Л.Р.'!J20+'[5]Корсак В.І.'!J20+[5]Конякіна!J20 -> 0 | K20: =SUM(I20:J20) -> 0 | L20: ='Солар Вест'!L20+Будник!L20 -> 0 | M20: ='Солар Вест'!M20+Будник!M20 -> 0 | N20: =SUM(L20:M20) -> 0 | O20: ='[5]ПП ВДГ'!O20+'[5]Корсак Л.Р.'!O20+'[5]Корсак В.І.'!O20+[5]Конякіна!O20 -> 0 | P20: ='[5]ПП ВДГ'!P20+'[5]Корсак Л.Р.'!P20+'[5]Корсак В.І.'!P20+[5]Конякіна!P20 -> 0 | Q20: =SUM(O20:P20) -> 0 | R20: ='Солар Вест'!R20+Будник!R20 -> 0 | S20: ='Солар Вест'!S20+Будник!S20 -> 0 | T20: =SUM(R20:S20) -> 0 | U20: ='[5]ПП ВДГ'!U20+'[5]Корсак Л.Р.'!U20+'[5]Корсак В.І.'!U20+[5]Конякіна!U20 -> 0 | V20: ='[5]ПП ВДГ'!V20+'[5]Корсак Л.Р.'!V20+'[5]Корсак В.І.'!V20+[5]Конякіна!V20 -> 0 | W20: =SUM(U20:V20) -> 0 | X20: ='Солар Вест'!X20+Будник!X20 -> 0 | Y20: ='Солар Вест'!Y20+Будник!Y20 -> 0 | Z20: =SUM(X20:Y20) -> 0 | AA20: ='[5]ПП ВДГ'!AA20+'[5]Корсак Л.Р.'!AA20+'[5]Корсак В.І.'!AA20+[5]Конякіна!AA20 -> 0 | AB20: ='[5]ПП ВДГ'!AB20+'[5]Корсак Л.Р.'!AB20+'[5]Корсак В.І.'!AB20+[5]Конякіна!AB20 -> 3200 | AC20: =SUM(AA20:AB20) -> 3200 | AD20: ='Солар Вест'!AD20+Будник!AD20 -> 0 | AE20: ='Солар Вест'!AE20+Будник!AE20 -> 0 | AF20: =SUM(AD20:AE20) -> 0 | AG20: ='[5]ПП ВДГ'!AG20+'[5]Корсак Л.Р.'!AG20+'[5]Корсак В.І.'!AG20+[5]Конякіна!AG20 -> 0 | AH20: ='[5]ПП ВДГ'!AH20+'[5]Корсак Л.Р.'!AH20+'[5]Корсак В.І.'!AH20+[5]Конякіна!AH20 -> 3500 | AI20: =SUM(AG20:AH20) -> 3500 | AJ20: ='Солар Вест'!AJ20+Будник!AJ20 -> 0 | AK20: ='Солар Вест'!AK20+Будник!AK20 -> 0 | AL20: =SUM(AJ20:AK20) -> 0 | AM20: ='[5]ПП ВДГ'!AM20+'[5]Корсак Л.Р.'!AM20+'[5]Корсак В.І.'!AM20+[5]Конякіна!AM20 -> 0 | AN20: ='[5]ПП ВДГ'!AN20+'[5]Корсак Л.Р.'!AN20+'[5]Корсак В.І.'!AN20+[5]Конякіна!AN20 -> 3700 | AO20: =SUM(AM20:AN20) -> 3700 | AP20: ='Солар Вест'!AP20+Будник!AP20 -> 0 | AQ20: ='Солар Вест'!AQ20+Будник!AQ20 -> 0 | AR20: =SUM(AP20:AQ20) -> 0 | AS20: ='[5]ПП ВДГ'!AS20+'[5]Корсак Л.Р.'!AS20+'[5]Корсак В.І.'!AS20+[5]Конякіна!AS20 -> 0 | AT20: ='[5]ПП ВДГ'!AT20+'[5]Корсак Л.Р.'!AT20+'[5]Корсак В.І.'!AT20+[5]Конякіна!AT20 -> 3700 | AU20: =SUM(AS20:AT20) -> 3700 | AV20: ='Солар Вест'!AV20+Будник!AV20 -> 0 | AW20: ='Солар Вест'!AW20+Будник!AW20 -> 0 | AX20: =SUM(AV20:AW20) -> 0 | AY20: ='[5]ПП ВДГ'!AY20+'[5]Корсак Л.Р.'!AY20+'[5]Корсак В.І.'!AY20+[5]Конякіна!AY20 -> 0 | AZ20: ='[5]ПП ВДГ'!AZ20+'[5]Корсак Л.Р.'!AZ20+'[5]Корсак В.І.'!AZ20+[5]Конякіна!AZ20 -> 0 | BA20: =SUM(AY20:AZ20) -> 0 | BB20: ='Солар Вест'!BB20+Будник!BB20 -> 0 | BC20: ='Солар Вест'!BC20+Будник!BC20 -> 0 | BD20: =SUM(BB20:BC20) -> 0 | BE20: ='Солар Вест'!BE20+Будник!BE20 -> 0 | BF20: ='Солар Вест'!BF20+Будник!BF20 -> 0 | BG20: =SUM(BE20:BF20) -> 0 | BH20: ='Солар Вест'!BH20+Будник!BH20 -> 0 | BI20: ='Солар Вест'!BI20+Будник!BI20 -> 0 | BJ20: =SUM(BH20:BI20) -> 0 | BK20: ='[5]ПП ВДГ'!BK20+'[5]Корсак Л.Р.'!BK20+'[5]Корсак В.І.'!BK20+[5]Конякіна!BK20 -> 0 | BL20: ='[5]ПП ВДГ'!BL20+'[5]Корсак Л.Р.'!BL20+'[5]Корсак В.І.'!BL20+[5]Конякіна!BL20 -> 0 | BM20: =SUM(BK20:BL20) -> 0 | BN20: ='Солар Вест'!BN20+Будник!BN20 -> 0 | BO20: ='Солар Вест'!BO20+Будник!BO20 -> 0 | BP20: =SUM(BN20:BO20) -> 0 | BQ20: ='[5]ПП ВДГ'!BQ20+'[5]Корсак Л.Р.'!BQ20+'[5]Корсак В.І.'!BQ20+[5]Конякіна!BQ20 -> 0 | BR20: ='[5]ПП ВДГ'!BR20+'[5]Корсак Л.Р.'!BR20+'[5]Корсак В.І.'!BR20+[5]Конякіна!BR20 -> 0 | BS20: =SUM(BQ20:BR20) -> 0 | BT20: ='Солар Вест'!BT20+Будник!BT20 -> 0 | BU20: ='Солар Вест'!BU20+Будник!BU20 -> 0 | BV20: =SUM(BT20:BU20) -> 0 | BW20: =+C20+I20+O20+AA20+AG20+U20+AM20+AS20+AY20+BE20+BK20+BQ20 -> 0 | BX20: =+D20+J20+P20+AB20+AH20+V20+AN20+AT20+AZ20+BF20+BL20+BR20 -> 14100 | BY20: =SUM(BW20:BX20) -> 14100 | BZ20: =+F20+L20+R20+AD20+AJ20+X20+AP20+AV20+BB20+BH20+BN20+BT20 -> 0 | CA20: =+G20+M20+S20+AE20+AK20+Y20+AQ20+AW20+BC20+BI20+BO20+BU20 -> 0 | CB20: =SUM(BZ20:CA20) -> 0
A21: 211 | B21: Отримання кредитів та позик | C21: ='[5]ПП ВДГ'!C21+'[5]Корсак Л.Р.'!C21+'[5]Корсак В.І.'!C21+[5]Конякіна!C21 -> 0 | D21: ='[5]ПП ВДГ'!D21+'[5]Корсак Л.Р.'!D21+'[5]Корсак В.І.'!D21+[5]Конякіна!D21 -> 0 | E21: =SUM(C21:D21) -> 0 | F21: ='Солар Вест'!F21+Будник!F21 -> 0 | G21: ='Солар Вест'!G21+Будник!G21 -> 0 | H21: =SUM(F21:G21) -> 0 | I21: ='[5]ПП ВДГ'!I21+'[5]Корсак Л.Р.'!I21+'[5]Корсак В.І.'!I21+[5]Конякіна!I21 -> 0 | J21: ='[5]ПП ВДГ'!J21+'[5]Корсак Л.Р.'!J21+'[5]Корсак В.І.'!J21+[5]Конякіна!J21 -> 0 | K21: =SUM(I21:J21) -> 0 | L21: ='Солар Вест'!L21+Будник!L21 -> 0 | M21: ='Солар Вест'!M21+Будник!M21 -> 0 | N21: =SUM(L21:M21) -> 0 | O21: ='[5]ПП ВДГ'!O21+'[5]Корсак Л.Р.'!O21+'[5]Корсак В.І.'!O21+[5]Конякіна!O21 -> 0 | P21: ='[5]ПП ВДГ'!P21+'[5]Корсак Л.Р.'!P21+'[5]Корсак В.І.'!P21+[5]Конякіна!P21 -> 0 | Q21: =SUM(O21:P21) -> 0 | R21: ='Солар Вест'!R21+Будник!R21 -> 0 | S21: ='Солар Вест'!S21+Будник!S21 -> 0 | T21: =SUM(R21:S21) -> 0 | U21: ='[5]ПП ВДГ'!U21+'[5]Корсак Л.Р.'!U21+'[5]Корсак В.І.'!U21+[5]Конякіна!U21 -> 0 | V21: ='[5]ПП ВДГ'!V21+'[5]Корсак Л.Р.'!V21+'[5]Корсак В.І.'!V21+[5]Конякіна!V21 -> 0 | W21: =SUM(U21:V21) -> 0 | X21: ='Солар Вест'!X21+Будник!X21 -> 0 | Y21: ='Солар Вест'!Y21+Будник!Y21 -> 0 | Z21: =SUM(X21:Y21) -> 0 | AA21: ='[5]ПП ВДГ'!AA21+'[5]Корсак Л.Р.'!AA21+'[5]Корсак В.І.'!AA21+[5]Конякіна!AA21 -> 0 | AB21: ='[5]ПП ВДГ'!AB21+'[5]Корсак Л.Р.'!AB21+'[5]Корсак В.І.'!AB21+[5]Конякіна!AB21 -> 0 | AC21: =SUM(AA21:AB21) -> 0 | AD21: ='Солар Вест'!AD21+Будник!AD21 -> 0 | AE21: ='Солар Вест'!AE21+Будник!AE21 -> 0 | AF21: =SUM(AD21:AE21) -> 0 | AG21: ='[5]ПП ВДГ'!AG21+'[5]Корсак Л.Р.'!AG21+'[5]Корсак В.І.'!AG21+[5]Конякіна!AG21 -> 0 | AH21: ='[5]ПП ВДГ'!AH21+'[5]Корсак Л.Р.'!AH21+'[5]Корсак В.І.'!AH21+[5]Конякіна!AH21 -> 0 | AI21: =SUM(AG21:AH21) -> 0 | AJ21: ='Солар Вест'!AJ21+Будник!AJ21 -> 0 | AK21: ='Солар Вест'!AK21+Будник!AK21 -> 0 | AL21: =SUM(AJ21:AK21) -> 0 | AM21: ='[5]ПП ВДГ'!AM21+'[5]Корсак Л.Р.'!AM21+'[5]Корсак В.І.'!AM21+[5]Конякіна!AM21 -> 0 | AN21: ='[5]ПП ВДГ'!AN21+'[5]Корсак Л.Р.'!AN21+'[5]Корсак В.І.'!AN21+[5]Конякіна!AN21 -> 0 | AO21: =SUM(AM21:AN21) -> 0 | AP21: ='Солар Вест'!AP21+Будник!AP21 -> 0 | AQ21: ='Солар Вест'!AQ21+Будник!AQ21 -> 0 | AR21: =SUM(AP21:AQ21) -> 0 | AS21: ='[5]ПП ВДГ'!AS21+'[5]Корсак Л.Р.'!AS21+'[5]Корсак В.І.'!AS21+[5]Конякіна!AS21 -> 0 | AT21: ='[5]ПП ВДГ'!AT21+'[5]Корсак Л.Р.'!AT21+'[5]Корсак В.І.'!AT21+[5]Конякіна!AT21 -> 0 | AU21: =SUM(AS21:AT21) -> 0 | AV21: ='Солар Вест'!AV21+Будник!AV21 -> 0 | AW21: ='Солар Вест'!AW21+Будник!AW21 -> 0 | AX21: =SUM(AV21:AW21) -> 0 | AY21: ='[5]ПП ВДГ'!AY21+'[5]Корсак Л.Р.'!AY21+'[5]Корсак В.І.'!AY21+[5]Конякіна!AY21 -> 0 | AZ21: ='[5]ПП ВДГ'!AZ21+'[5]Корсак Л.Р.'!AZ21+'[5]Корсак В.І.'!AZ21+[5]Конякіна!AZ21 -> 0 | BA21: =SUM(AY21:AZ21) -> 0 | BB21: ='Солар Вест'!BB21+Будник!BB21 -> 0 | BC21: ='Солар Вест'!BC21+Будник!BC21 -> 0 | BD21: =SUM(BB21:BC21) -> 0 | BE21: ='Солар Вест'!BE21+Будник!BE21 -> 0 | BF21: ='Солар Вест'!BF21+Будник!BF21 -> 0 | BG21: =SUM(BE21:BF21) -> 0 | BH21: ='Солар Вест'!BH21+Будник!BH21 -> 0 | BI21: ='Солар Вест'!BI21+Будник!BI21 -> 0 | BJ21: =SUM(BH21:BI21) -> 0 | BK21: ='[5]ПП ВДГ'!BK21+'[5]Корсак Л.Р.'!BK21+'[5]Корсак В.І.'!BK21+[5]Конякіна!BK21 -> 0 | BL21: ='[5]ПП ВДГ'!BL21+'[5]Корсак Л.Р.'!BL21+'[5]Корсак В.І.'!BL21+[5]Конякіна!BL21 -> 0 | BM21: =SUM(BK21:BL21) -> 0 | BN21: ='Солар Вест'!BN21+Будник!BN21 -> 0 | BO21: ='Солар Вест'!BO21+Будник!BO21 -> 0 | BP21: =SUM(BN21:BO21) -> 0 | BQ21: ='[5]ПП ВДГ'!BQ21+'[5]Корсак Л.Р.'!BQ21+'[5]Корсак В.І.'!BQ21+[5]Конякіна!BQ21 -> 0 | BR21: ='[5]ПП ВДГ'!BR21+'[5]Корсак Л.Р.'!BR21+'[5]Корсак В.І.'!BR21+[5]Конякіна!BR21 -> 0 | BS21: =SUM(BQ21:BR21) -> 0 | BT21: ='Солар Вест'!BT21+Будник!BT21 -> 0 | BU21: ='Солар Вест'!BU21+Будник!BU21 -> 0 | BV21: =SUM(BT21:BU21) -> 0 | BW21: =+C21+I21+O21+AA21+AG21+U21+AM21+AS21+AY21+BE21+BK21+BQ21 -> 0 | BX21: =+D21+J21+P21+AB21+AH21+V21+AN21+AT21+AZ21+BF21+BL21+BR21 -> 0 | BY21: =SUM(BW21:BX21) -> 0 | BZ21: =+F21+L21+R21+AD21+AJ21+X21+AP21+AV21+BB21+BH21+BN21+BT21 -> 0 | CA21: =+G21+M21+S21+AE21+AK21+Y21+AQ21+AW21+BC21+BI21+BO21+BU21 -> 0 | CB21: =SUM(BZ21:CA21) -> 0
A22: 212 | B22: Отримання фінансових позик | C22: ='[5]ПП ВДГ'!C22+'[5]Корсак Л.Р.'!C22+'[5]Корсак В.І.'!C22+[5]Конякіна!C22 -> 0 | D22: ='[5]ПП ВДГ'!D22+'[5]Корсак Л.Р.'!D22+'[5]Корсак В.І.'!D22+[5]Конякіна!D22 -> 0 | E22: =SUM(C22:D22) -> 0 | F22: ='Солар Вест'!F22+Будник!F22 -> 292000 | G22: ='Солар Вест'!G22+Будник!G22 -> 0 | H22: =SUM(F22:G22) -> 292000 | I22: ='[5]ПП ВДГ'!I22+'[5]Корсак Л.Р.'!I22+'[5]Корсак В.І.'!I22+[5]Конякіна!I22 -> 0 | J22: ='[5]ПП ВДГ'!J22+'[5]Корсак Л.Р.'!J22+'[5]Корсак В.І.'!J22+[5]Конякіна!J22 -> 0 | K22: =SUM(I22:J22) -> 0 | L22: ='Солар Вест'!L22+Будник!L22 -> 141000 | M22: ='Солар Вест'!M22+Будник!M22 -> 0 | N22: =SUM(L22:M22) -> 141000 | O22: ='[5]ПП ВДГ'!O22+'[5]Корсак Л.Р.'!O22+'[5]Корсак В.І.'!O22+[5]Конякіна!O22 -> 1700 | P22: ='[5]ПП ВДГ'!P22+'[5]Корсак Л.Р.'!P22+'[5]Корсак В.І.'!P22+[5]Конякіна!P22 -> 0 | Q22: =SUM(O22:P22) -> 1700 | R22: ='Солар Вест'!R22+Будник!R22 -> 2060000 | S22: ='Солар Вест'!S22+Будник!S22 -> 0 | T22: =SUM(R22:S22) -> 2060000 | U22: ='[5]ПП ВДГ'!U22+'[5]Корсак Л.Р.'!U22+'[5]Корсак В.І.'!U22+[5]Конякіна!U22 -> 0 | V22: ='[5]ПП ВДГ'!V22+'[5]Корсак Л.Р.'!V22+'[5]Корсак В.І.'!V22+[5]Конякіна!V22 -> 0 | W22: =SUM(U22:V22) -> 0 | X22: ='Солар Вест'!X22+Будник!X22 -> 0 | Y22: ='Солар Вест'!Y22+Будник!Y22 -> 0 | Z22: =SUM(X22:Y22) -> 0 | AA22: ='[5]ПП ВДГ'!AA22+'[5]Корсак Л.Р.'!AA22+'[5]Корсак В.І.'!AA22+[5]Конякіна!AA22 -> 1800 | AB22: ='[5]ПП ВДГ'!AB22+'[5]Корсак Л.Р.'!AB22+'[5]Корсак В.І.'!AB22+[5]Конякіна!AB22 -> 0 | AC22: =SUM(AA22:AB22) -> 1800 | AD22: ='Солар Вест'!AD22+Будник!AD22 -> 72000 | AE22: ='Солар Вест'!AE22+Будник!AE22 -> 0 | AF22: =SUM(AD22:AE22) -> 72000 | AG22: ='[5]ПП ВДГ'!AG22+'[5]Корсак Л.Р.'!AG22+'[5]Корсак В.І.'!AG22+[5]Конякіна!AG22 -> 1800 | AH22: ='[5]ПП ВДГ'!AH22+'[5]Корсак Л.Р.'!AH22+'[5]Корсак В.І.'!AH22+[5]Конякіна!AH22 -> 0 | AI22: =SUM(AG22:AH22) -> 1800 | AJ22: ='Солар Вест'!AJ22+Будник!AJ22 -> 458000 | AK22: ='Солар Вест'!AK22+Будник!AK22 -> 0 | AL22: =SUM(AJ22:AK22) -> 458000 | AM22: ='[5]ПП ВДГ'!AM22+'[5]Корсак Л.Р.'!AM22+'[5]Корсак В.І.'!AM22+[5]Конякіна!AM22 -> 1750 | AN22: ='[5]ПП ВДГ'!AN22+'[5]Корсак Л.Р.'!AN22+'[5]Корсак В.І.'!AN22+[5]Конякіна!AN22 -> 0 | AO22: =SUM(AM22:AN22) -> 1750 | AP22: ='Солар Вест'!AP22+Будник!AP22 -> 241100 | AQ22: ='Солар Вест'!AQ22+Будник!AQ22 -> 0 | AR22: =SUM(AP22:AQ22) -> 241100 | AS22: ='[5]ПП ВДГ'!AS22+'[5]Корсак Л.Р.'!AS22+'[5]Корсак В.І.'!AS22+[5]Конякіна!AS22 -> 1800 | AT22: ='[5]ПП ВДГ'!AT22+'[5]Корсак Л.Р.'!AT22+'[5]Корсак В.І.'!AT22+[5]Конякіна!AT22 -> 0 | AU22: =SUM(AS22:AT22) -> 1800 | AV22: ='Солар Вест'!AV22+Будник!AV22 -> 0 | AW22: ='Солар Вест'!AW22+Будник!AW22 -> 0 | AX22: =SUM(AV22:AW22) -> 0 | AY22: ='[5]ПП ВДГ'!AY22+'[5]Корсак Л.Р.'!AY22+'[5]Корсак В.І.'!AY22+[5]Конякіна!AY22 -> 1700 | AZ22: ='[5]ПП ВДГ'!AZ22+'[5]Корсак Л.Р.'!AZ22+'[5]Корсак В.І.'!AZ22+[5]Конякіна!AZ22 -> 0 | BA22: =SUM(AY22:AZ22) -> 1700 | BB22: ='Солар Вест'!BB22+Будник!BB22 -> 0 | BC22: ='Солар Вест'!BC22+Будник!BC22 -> 0 | BD22: =SUM(BB22:BC22) -> 0 | BE22: ='Солар Вест'!BE22+Будник!BE22 -> 0 | BF22: ='Солар Вест'!BF22+Будник!BF22 -> 0 | BG22: =SUM(BE22:BF22) -> 0 | BH22: ='Солар Вест'!BH22+Будник!BH22 -> 0 | BI22: ='Солар Вест'!BI22+Будник!BI22 -> 0 | BJ22: =SUM(BH22:BI22) -> 0 | BK22: ='[5]ПП ВДГ'!BK22+'[5]Корсак Л.Р.'!BK22+'[5]Корсак В.І.'!BK22+[5]Конякіна!BK22 -> 1850 | BL22: ='[5]ПП ВДГ'!BL22+'[5]Корсак Л.Р.'!BL22+'[5]Корсак В.І.'!BL22+[5]Конякіна!BL22 -> 0 | BM22: =SUM(BK22:BL22) -> 1850 | BN22: ='Солар Вест'!BN22+Будник!BN22 -> 0 | BO22: ='Солар Вест'!BO22+Будник!BO22 -> 0 | BP22: =SUM(BN22:BO22) -> 0 | BQ22: ='[5]ПП ВДГ'!BQ22+'[5]Корсак Л.Р.'!BQ22+'[5]Корсак В.І.'!BQ22+[5]Конякіна!BQ22 -> 1900 | BR22: ='[5]ПП ВДГ'!BR22+'[5]Корсак Л.Р.'!BR22+'[5]Корсак В.І.'!BR22+[5]Конякіна!BR22 -> 0 | BS22: =SUM(BQ22:BR22) -> 1900 | BT22: ='Солар Вест'!BT22+Будник!BT22 -> 0 | BU22: ='Солар Вест'!BU22+Будник!BU22 -> 0 | BV22: =SUM(BT22:BU22) -> 0 | BW22: =+C22+I22+O22+AA22+AG22+U22+AM22+AS22+AY22+BE22+BK22+BQ22 -> 14300 | BX22: =+D22+J22+P22+AB22+AH22+V22+AN22+AT22+AZ22+BF22+BL22+BR22 -> 0 | BY22: =SUM(BW22:BX22) -> 14300 | BZ22: =+F22+L22+R22+AD22+AJ22+X22+AP22+AV22+BB22+BH22+BN22+BT22 -> 3264100 | CA22: =+G22+M22+S22+AE22+AK22+Y22+AQ22+AW22+BC22+BI22+BO22+BU22 -> 0 | CB22: =SUM(BZ22:CA22) -> 3264100
B23: в т.ч. внутрішньогрупове отримання фінансових позик | C23: ='[5]ПП ВДГ'!C23+'[5]Корсак Л.Р.'!C23+'[5]Корсак В.І.'!C23+[5]Конякіна!C23 -> 0 | D23: ='[5]ПП ВДГ'!D23+'[5]Корсак Л.Р.'!D23+'[5]Корсак В.І.'!D23+[5]Конякіна!D23 -> 0 | E23: =SUM(C23:D23) -> 0 | F23: ='Солар Вест'!F23+Будник!F23 -> 0 | G23: ='Солар Вест'!G23+Будник!G23 -> 0 | H23: =SUM(F23:G23) -> 0 | I23: ='[5]ПП ВДГ'!I23+'[5]Корсак Л.Р.'!I23+'[5]Корсак В.І.'!I23+[5]Конякіна!I23 -> 0 | J23: ='[5]ПП ВДГ'!J23+'[5]Корсак Л.Р.'!J23+'[5]Корсак В.І.'!J23+[5]Конякіна!J23 -> 0 | K23: =SUM(I23:J23) -> 0 | L23: ='Солар Вест'!L23+Будник!L23 -> 0 | M23: ='Солар Вест'!M23+Будник!M23 -> 0 | N23: =SUM(L23:M23) -> 0 | O23: ='[5]ПП ВДГ'!O23+'[5]Корсак Л.Р.'!O23+'[5]Корсак В.І.'!O23+[5]Конякіна!O23 -> 1700 | P23: ='[5]ПП ВДГ'!P23+'[5]Корсак Л.Р.'!P23+'[5]Корсак В.І.'!P23+[5]Конякіна!P23 -> 0 | Q23: =SUM(O23:P23) -> 1700 | R23: ='Солар Вест'!R23+Будник!R23 -> 0 | S23: ='Солар Вест'!S23+Будник!S23 -> 0 | T23: =SUM(R23:S23) -> 0 | U23: ='[5]ПП ВДГ'!U23+'[5]Корсак Л.Р.'!U23+'[5]Корсак В.І.'!U23+[5]Конякіна!U23 -> 0 | V23: ='[5]ПП ВДГ'!V23+'[5]Корсак Л.Р.'!V23+'[5]Корсак В.І.'!V23+[5]Конякіна!V23 -> 0 | W23: =SUM(U23:V23) -> 0 | X23: ='Солар Вест'!X23+Будник!X23 -> 0 | Y23: ='Солар Вест'!Y23+Будник!Y23 -> 0 | Z23: =SUM(X23:Y23) -> 0 | AA23: ='[5]ПП ВДГ'!AA23+'[5]Корсак Л.Р.'!AA23+'[5]Корсак В.І.'!AA23+[5]Конякіна!AA23 -> 1800 | AB23: ='[5]ПП ВДГ'!AB23+'[5]Корсак Л.Р.'!AB23+'[5]Корсак В.І.'!AB23+[5]Конякіна!AB23 -> 0 | AC23: =SUM(AA23:AB23) -> 1800 | AD23: ='Солар Вест'!AD23+Будник!AD23 -> 0 | AE23: ='Солар Вест'!AE23+Будник!AE23 -> 0 | AF23: =SUM(AD23:AE23) -> 0 | AG23: ='[5]ПП ВДГ'!AG23+'[5]Корсак Л.Р.'!AG23+'[5]Корсак В.І.'!AG23+[5]Конякіна!AG23 -> 1800 | AH23: ='[5]ПП ВДГ'!AH23+'[5]Корсак Л.Р.'!AH23+'[5]Корсак В.І.'!AH23+[5]Конякіна!AH23 -> 0 | AI23: =SUM(AG23:AH23) -> 1800 | AJ23: ='Солар Вест'!AJ23+Будник!AJ23 -> 0 | AK23: ='Солар Вест'!AK23+Будник!AK23 -> 0 | AL23: =SUM(AJ23:AK23) -> 0 | AM23: ='[5]ПП ВДГ'!AM23+'[5]Корсак Л.Р.'!AM23+'[5]Корсак В.І.'!AM23+[5]Конякіна!AM23 -> 1750 | AN23: ='[5]ПП ВДГ'!AN23+'[5]Корсак Л.Р.'!AN23+'[5]Корсак В.І.'!AN23+[5]Конякіна!AN23 -> 0 | AO23: =SUM(AM23:AN23) -> 1750 | AP23: ='Солар Вест'!AP23+Будник!AP23 -> 0 | AQ23: ='Солар Вест'!AQ23+Будник!AQ23 -> 0 | AR23: =SUM(AP23:AQ23) -> 0 | AS23: ='[5]ПП ВДГ'!AS23+'[5]Корсак Л.Р.'!AS23+'[5]Корсак В.І.'!AS23+[5]Конякіна!AS23 -> 1800 | AT23: ='[5]ПП ВДГ'!AT23+'[5]Корсак Л.Р.'!AT23+'[5]Корсак В.І.'!AT23+[5]Конякіна!AT23 -> 0 | AU23: =SUM(AS23:AT23) -> 1800 | AV23: ='Солар Вест'!AV23+Будник!AV23 -> 0 | AW23: ='Солар Вест'!AW23+Будник!AW23 -> 0 | AX23: =SUM(AV23:AW23) -> 0 | AY23: ='[5]ПП ВДГ'!AY23+'[5]Корсак Л.Р.'!AY23+'[5]Корсак В.І.'!AY23+[5]Конякіна!AY23 -> 1700 | AZ23: ='[5]ПП ВДГ'!AZ23+'[5]Корсак Л.Р.'!AZ23+'[5]Корсак В.І.'!AZ23+[5]Конякіна!AZ23 -> 0 | BA23: =SUM(AY23:AZ23) -> 1700 | BB23: ='Солар Вест'!BB23+Будник!BB23 -> 0 | BC23: ='Солар Вест'!BC23+Будник!BC23 -> 0 | BD23: =SUM(BB23:BC23) -> 0 | BE23: ='Солар Вест'!BE23+Будник!BE23 -> 0 | BF23: ='Солар Вест'!BF23+Будник!BF23 -> 0 | BG23: =SUM(BE23:BF23) -> 0 | BH23: ='Солар Вест'!BH23+Будник!BH23 -> 0 | BI23: ='Солар Вест'!BI23+Будник!BI23 -> 0 | BJ23: =SUM(BH23:BI23) -> 0 | BK23: ='[5]ПП ВДГ'!BK23+'[5]Корсак Л.Р.'!BK23+'[5]Корсак В.І.'!BK23+[5]Конякіна!BK23 -> 1850 | BL23: ='[5]ПП ВДГ'!BL23+'[5]Корсак Л.Р.'!BL23+'[5]Корсак В.І.'!BL23+[5]Конякіна!BL23 -> 0 | BM23: =SUM(BK23:BL23) -> 1850 | BN23: ='Солар Вест'!BN23+Будник!BN23 -> 0 | BO23: ='Солар Вест'!BO23+Будник!BO23 -> 0 | BP23: =SUM(BN23:BO23) -> 0 | BQ23: ='[5]ПП ВДГ'!BQ23+'[5]Корсак Л.Р.'!BQ23+'[5]Корсак В.І.'!BQ23+[5]Конякіна!BQ23 -> 1900 | BR23: ='[5]ПП ВДГ'!BR23+'[5]Корсак Л.Р.'!BR23+'[5]Корсак В.І.'!BR23+[5]Конякіна!BR23 -> 0 | BS23: =SUM(BQ23:BR23) -> 1900 | BT23: ='Солар Вест'!BT23+Будник!BT23 -> 0 | BU23: ='Солар Вест'!BU23+Будник!BU23 -> 0 | BV23: =SUM(BT23:BU23) -> 0 | BW23: =+C23+I23+O23+AA23+AG23+U23+AM23+AS23+AY23+BE23+BK23+BQ23 -> 14300 | BX23: =+D23+J23+P23+AB23+AH23+V23+AN23+AT23+AZ23+BF23+BL23+BR23 -> 0 | BY23: =SUM(BW23:BX23) -> 14300 | BZ23: =+F23+L23+R23+AD23+AJ23+X23+AP23+AV23+BB23+BH23+BN23+BT23 -> 0 | CA23: =+G23+M23+S23+AE23+AK23+Y23+AQ23+AW23+BC23+BI23+BO23+BU23 -> 0 | CB23: =SUM(BZ23:CA23) -> 0
